Workbook

Sheet נתונים והנחות
B1: מקרא צבעים
B2: ערך להזנה
B3: נתון לעדכון / בקרה
B4: נתון ממקור אמיתי (לא הערכה)
B5: נתון מוערך/נגזר (עם מקור)
B6: תרחיש A — טכנולוגיה קיימת
B7: תרחיש B — יעיל, ללא תמריץ
B8: תרחיש C — יעיל, עם תמריץ
B9: 1. פרמטרים פיננסיים
B10: שיעור מס חברות | C10: % | D10: רשות המסים | F10: 0.23
B11: שיעור היוון (יזמי / פרטי) | C11: % | D11: סוכם עם דניאל | E11: 6% — הוחלט עם דניאל 2026-07-13 (לעומת 10% תעשייתי שנשקל קודם) | F11: 0.06
B12: מחיר חשמל ממוצע לתעשייה | C12: אג'/קוט"ש | D12: חברת החשמל | E12: ממוצע SMP 2024 — נתון כללי, ייתכן שיעודכן לממוצע משוקלל לפי שעות תעו"ז | F12: 14
B14: 1ב. מחירי דלקים ומקדמי המרה (עבור בסיס משאבות חום)
B15: מחיר סולר בתעשייה | C15: ₪/ליטר | D15: משרד האנרגיה 2024 [1] | E15: מחירים תיאורטיים של מוצרי דלק שאינם בפיקוח, לפני מע"מ ובלו | F15: 2.59368
B16: מחיר מזוט בתעשייה | C16: ₪/טון | D16: משרד האנרגיה 2024 [1] | E16: תוקן מהיחידה שהוזנה במקור (₪/ק"ג -> ₪/טון) — הערך המקורי לא עקבי עם טווח המחירים בדוח המקורי | F16: 2344.72
B17: יחס קלורי — סולר | C17: טון דלק/MWh | D17: אקסל של עמרי (MRV) [2] | F17: 0.085
B18: יחס קלורי — מזוט | C18: טון דלק/MWh | D18: אקסל של עמרי (MRV) [2] | F18: 0.088
B19: צפיפות סולר | C19: ק"ג/ליטר | D19: אקסל של עמרי (MRV) [2] | E19: להמרת טון סולר לליטר במידה ונבחר סולר כדלק בסיס | F19: 0.82
B21: 2. פרמטר תמריץ — מכפיל פחת (פחת מואץ)
B22: מכפיל שיעור הפחת ← פרמטר המדיניות המרכזי | C22: מכפיל | D22: פרמטר ניתן לשינוי | E22: 1.0 = ללא תמריץ | 2.0 = קפריסין (כפול, 5 שנים) | 5.0 = 2 שנים | F22: 2
B23: מכפיל 2.0 + פחת סטנדרטי 10% = שיעור מואץ 20%/שנה למשך 5 שנים. סה"כ ניכוי = 100% CapEx — היתרון הוא קדמות הניכוי (Time Value of Money).
B24: דוגמאות: 1.0 = 10%/שנה × 10 שנים (סטנדרטי) | 2.0 = 20%/שנה × 5 שנים | 3.33 = 33%/שנה × 3 שנים | 5.0 = 50%/שנה × 2 שנים (מודל קפריסין/אירלנד)
B26: 3. שיעורי פחת סטנדרטיים — תקנות מס הכנסה
B27: משאבות חום | C27: % לשנה | D27: תקנות פחת | E27: ציוד מכני | F27: 0.1
B28: צ'ילרים | C28: % לשנה | D28: תקנות פחת | E28: ציוד מכני | F28: 0.1
B29: מדחסי VSD | C29: % לשנה | D29: תקנות פחת | E29: ציוד מכני | F29: 0.1
B31: * שיעורי הפחת הם הנחות עבודה — יש לוודא מול יועץ מס לפני הגשה
B33: 4. הנחות לפי טכנולוגיה — כל הנתונים לעדכון בטבלה זו
B34: פרמטר | C34: יחידות | D34: מקור | E34: הערות | F34: משאבות חום (חימום מים) | G34: צ'ילרים | H34: מדחסי VSD
F35: vs. תנור מזוט/סולר | G35: vs. מערכת קירור קונבנציונלית | H35: vs. מדחס מהירות קבועה
B36: קיבולת מותקנת | C36: ראו הערה | D36: baseline-technology-data.md — נקודת קיבולת נבחרת | F36: 40 | G36: 500 | H36: 45
B37: שעות פעילות שנתיות | C37: שעות | D37: ראו הערה בעמודת הטכנולוגיה | E37: ממתין לייעוץ מהנדס EcoTraders (משאבות חום) | צ'ילרים: 3,000 שעות (מספר עבודה) | VSD: 6,400 שעות (אמצע 6,000-6,800) | F37: PENDING | G37: 3000 | H37: 6400
B38: COP — משאבת חום (יעיל) | C38: יחס | D38: Sprsun — עמוד מפרט מוצר [3] | E38: רלוונטי למשאבות חום בלבד | F38: 4.13
B39: יעילות בעירה — תנור בסיס | C39: % | D39: ASME PTC 4 [4] | E39: רלוונטי למשאבות חום בלבד | F39: 0.835
B40: סוג דלק בסיס | C40: טקסט | D40: הנחת עבודה — ניתן לשנות | E40: רלוונטי למשאבות חום בלבד — "מזוט" או "סולר" | F40: מזוט
B41: יעילות אנרגטית — בסיסי | C41: ראו הערה | D41: ראו הערה בעמודת הטכנולוגיה | E41: רלוונטי לצ'ילרים/VSD בלבד | G41: 0.6 | H41: 21.5
B42: יעילות אנרגטית — יעיל | C42: ראו הערה | D42: ראו הערה בעמודת הטכנולוגיה | E42: רלוונטי לצ'ילרים/VSD בלבד | G42: 0.48 | H42: 16.5
B43: חיסכון אנרגטי (מחושב) | C43: % מצריכה | D43: חישוב | E43: רלוונטי לצ'ילרים/VSD בלבד — נגזר משורות 41-42 | F43: - | G43: =IF(AND(ISNUMBER(G41),ISNUMBER(G42)),(G41-G42)/G41,"PENDING") | H43: =IF(AND(ISNUMBER(H41),ISNUMBER(H42)),(H41-H42)/H41,"PENDING")
B44: צריכת אנרגיה/דלק שנתית — בסיסי | C44: ראו הערה | D44: חישוב — קיבולת × שעות × יעילות/COP | E44: טון דלק (משאבות חום) | קוט"ש (צ'ילרים/VSD) | F44: =IF(AND(ISNUMBER(F36),ISNUMBER(F37),ISNUMBER(F39)),(F36*F37/1000/F39)*IF(F40="מזוט",'נתונים והנחות'!$F$18,'נתונים והנחות'!$F$17),"PENDING") | G44: =IF(AND(ISNUMBER(G36),ISNUMBER(G37),ISNUMBER(G41)),G36*G41*G37,"PENDING") | H44: =IF(AND(ISNUMBER(H36),ISNUMBER(H37)),H36*H37,"PENDING")
B45: צריכת חשמל שנתית — יעיל | C45: קוט"ש/שנה | D45: חישוב | E45: הצד היעיל תמיד חשמלי בכל הטכנולוגיות | F45: =IF(AND(ISNUMBER(F36),ISNUMBER(F37),ISNUMBER(F38)),F36*F37/F38,"PENDING") | G45: =IF(AND(ISNUMBER(G44),ISNUMBER(G43)),G44*(1-G43),"PENDING") | H45: =IF(AND(ISNUMBER(H44),ISNUMBER(H43)),H44*(1-H43),"PENDING")
...

Sheet ניתוח
B1: מקרא צבעים
B2: ערך להזנה
B3: נתון לעדכון / בקרה
B4: נתון ממקור אמיתי (לא הערכה)
B5: נתון מוערך/נגזר (עם מקור)
B6: תרחיש A — טכנולוגיה קיימת
B7: תרחיש B — יעיל, ללא תמריץ
B8: ניתוח כלכלי — פחת מואץ לפי טכנולוגיה | השוואת שלושה תרחישים
B9: פרמטר מדיניות מרכזי
B10: 1. פרמטרים פיננסיים
B11: שיעור מס חברות | C11: % | D11: נתונים והנחות | F11: ='נתונים והנחות'!$F$10
B12: שיעור היוון | C12: % | D12: נתונים והנחות | F12: ='נתונים והנחות'!$F$11
B13: מחיר חשמל (₪/קוט"ש) | C13: ₪/קוט"ש | D13: נתונים והנחות | F13: ='נתונים והנחות'!$F$12/100
B15: 2. פרמטר תמריץ — מכפיל פחת
B16: מכפיל שיעור הפחת ← שנה ב'נתונים והנחות'!F22 | C16: מכפיל | D16: נתונים והנחות | F16: ='נתונים והנחות'!$F$22
B17: מכפיל × פחת סטנדרטי = שיעור מואץ | סה"כ ניכוי = 100% CapEx | תקופת פחת = 1 ÷ שיעור מואץ
B19: 3. ניתוחים לפי טכנולוגיה
B21: 3.1 משאבות חום (חימום מים)
B22: * החלפת תנור מזוט/סולר במשאבת חום | אורך חיים: 10 vs 15 שנה | כל הנתונים: גיליון 'נתונים והנחות' — סעיף 4
B23: ב. לוחות פחת (ציוד בסיסי vs. יעיל)
B24: פרמטר | C24: יחידות | D24: מקור | E24: הערות | F24: שנה 0 (השקעה) | G24: שנה 1 | H24: שנה 2 | I24: שנה 3 | J24: שנה 4 | K24: שנה 5 | L24: שנה 6 | M24: שנה 7 | N24: שנה 8 | O24: שנה 9 | P24: שנה 10 | Q24: שנה 11 | R24: שנה 12 | S24: שנה 13 | T24: שנה 14 | U24: שנה 15 | V24: שנה 16 | W24: שנה 17 | X24: שנה 18 | Y24: שנה 19 | Z24: שנה 20
B25: פחת סטנדרטי — תנור מזוט/סולר | C25: ₪ | D25: חישוב | E25: קו ישר | 10%/שנה | עד 10 שנים | CapEx בסיסי | F25: 0 | G25: =IF(ISNUMBER('נתונים והנחות'!$F$47),'נתונים והנחות'!$F$47*0.1,0) | H25: =IF(ISNUMBER('נתונים והנחות'!$F$47),'נתונים והנחות'!$F$47*0.1,0) | I25: =IF(ISNUMBER('נתונים והנחות'!$F$47),'נתונים והנחות'!$F$47*0.1,0) | J25: =IF(ISNUMBER('נתונים והנחות'!$F$47),'נתונים והנחות'!$F$47*0.1,0) | K25: =IF(ISNUMBER('נתונים והנחות'!$F$47),'נתונים והנחות'!$F$47*0.1,0) | L25: =IF(ISNUMBER('נתונים והנחות'!$F$47),'נתונים והנחות'!$F$47*0.1,0) | M25: =IF(ISNUMBER('נתונים והנחות'!$F$47),'נתונים והנחות'!$F$47*0.1,0) | N25: =IF(ISNUMBER('נתונים והנחות'!$F$47),'נתונים והנחות'!$F$47*0.1,0) | ... P25: =IF(ISNUMBER('נתונים והנחות'!$F$47),'נתונים והנחות'!$F$47*0.1,0) | Q25: =0 | R25: =0 | S25: =0 | T25: =0 | U25: =0 | V25: =0 | W25: =0 | X25: =0 | ... Z25: =0
B26: מגן מס — תנור מזוט/סולר | C26: ₪ | D26: חישוב | E26: =פחת × שיעור מס | F26: 0 | G26: =G25*'נתונים והנחות'!$F$10 | H26: =H25*'נתונים והנחות'!$F$10 | I26: =I25*'נתונים והנחות'!$F$10 | J26: =J25*'נתונים והנחות'!$F$10 | K26: =K25*'נתונים והנחות'!$F$10 | L26: =L25*'נתונים והנחות'!$F$10 | M26: =M25*'נתונים והנחות'!$F$10 | N26: =N25*'נתונים והנחות'!$F$10 | ... Z26: =Z25*'נתונים והנחות'!$F$10
B27: פחת סטנדרטי — משאבות חום (חימום מים) | C27: ₪ | D27: חישוב | E27: קו ישר | 10%/שנה | עד 10 שנים | CapEx יעיל | F27: 0 | G27: =IF(ISNUMBER('נתונים והנחות'!$F$48),'נתונים והנחות'!$F$48*0.1,0) | H27: =IF(ISNUMBER('נתונים והנחות'!$F$48),'נתונים והנחות'!$F$48*0.1,0) | I27: =IF(ISNUMBER('נתונים והנחות'!$F$48),'נתונים והנחות'!$F$48*0.1,0) | J27: =IF(ISNUMBER('נתונים והנחות'!$F$48),'נתונים והנחות'!$F$48*0.1,0) | K27: =IF(ISNUMBER('נתונים והנחות'!$F$48),'נתונים והנחות'!$F$48*0.1,0) | L27: =IF(ISNUMBER('נתונים והנחות'!$F$48),'נתונים והנחות'!$F$48*0.1,0) | M27: =IF(ISNUMBER('נתונים והנחות'!$F$48),'נתונים והנחות'!$F$48*0.1,0) | N27: =IF(ISNUMBER('נתונים והנחות'!$F$48),'נתונים והנחות'!$F$48*0.1,0) | ... P27: =IF(ISNUMBER('נתונים והנחות'!$F$48),'נתונים והנחות'!$F$48*0.1,0) | Q27: =0 | R27: =0 | S27: =0 | T27: =0 | U27: =0 | V27: =0 | W27: =0 | X27: =0 | ... Z27: =0
B28: מגן מס סטנדרטי — משאבות חום (חימום מים) | C28: ₪ | D28: חישוב | E28: =פחת × שיעור מס | F28: 0 | G28: =G27*'נתונים והנחות'!$F$10 | H28: =H27*'נתונים והנחות'!$F$10 | I28: =I27*'נתונים והנחות'!$F$10 | J28: =J27*'נתונים והנחות'!$F$10 | K28: =K27*'נתונים והנחות'!$F$10 | L28: =L27*'נתונים והנחות'!$F$10 | M28: =M27*'נתונים והנחות'!$F$10 | N28: =N27*'נתונים והנחות'!$F$10 | ... Z28: =Z27*'נתונים והנחות'!$F$10
B29: פחת מואץ — משאבות חום (חימום מים) | C29: ₪ | D29: חישוב | E29: =CapEx יעיל × (פחת סטנדרטי × מכפיל) | תקופה = 1 ÷ שיעור מואץ | F29: 0 | G29: =IF(ISNUMBER('נתונים והנחות'!$F$48),IF(1<=ROUND(1/(0.1*'נתונים והנחות'!$F$22),0),'נתונים והנחות'!$F$48*0.1*'נתונים והנחות'!$F$22,0),0) | H29: =IF(ISNUMBER('נתונים והנחות'!$F$48),IF(2<=ROUND(1/(0.1*'נתונים והנחות'!$F$22),0),'נתונים והנחות'!$F$48*0.1*'נתונים והנחות'!$F$22,0),0) | I29: =IF(ISNUMBER('נתונים והנחות'!$F$48),IF(3<=ROUND(1/(0.1*'נתונים והנחות'!$F$22),0),'נתונים והנחות'!$F$48*0.1*'נתונים והנחות'!$F$22,0),0) | J29: =IF(ISNUMBER('נתונים והנחות'!$F$48),IF(4<=ROUND(1/(0.1*'נתונים והנחות'!$F$22),0),'נתונים והנחות'!$F$48*0.1*'נתונים והנחות'!$F$22,0),0) | K29: =IF(ISNUMBER('נתונים והנחות'!$F$48),IF(5<=ROUND(1/(0.1*'נתונים והנחות'!$F$22),0),'נתונים והנחות'!$F$48*0.1*'נתונים והנחות'!$F$22,0),0) | L29: =IF(ISNUMBER('נתונים והנחות'!$F$48),IF(6<=ROUND(1/(0.1*'נתונים והנחות'!$F$22),0),'נתונים והנחות'!$F$48*0.1*'נתונים והנחות'!$F$22,0),0) | M29: =IF(ISNUMBER('נתונים והנחות'!$F$48),IF(7<=ROUND(1/(0.1*'נתונים והנחות'!$F$22),0),'נתונים והנחות'!$F$48*0.1*'נתונים והנחות'!$F$22,0),0) | N29: =IF(ISNUMBER('נתונים והנחות'!$F$48),IF(8<=ROUND(1/(0.1*'נתונים והנחות'!$F$22),0),'נתונים והנחות'!$F$48*0.1*'נתונים והנחות'!$F$22,0),0) | O29: =IF(ISNUMBER('נתונים והנחות'!$F$48),IF(9<=ROUND(1/(0.1*'נתונים והנחות'!$F$22),0),'נתונים והנחות'!$F$48*0.1*'נתונים והנחות'!$F$22,0),0) | P29: =IF(ISNUMBER('נתונים והנחות'!$F$48),IF(10<=ROUND(1/(0.1*'נתונים והנחות'!$F$22),0),'נתונים והנחות'!$F$48*0.1*'נתונים והנחות'!$F$22,0),0) | Q29: =IF(ISNUMBER('נתונים והנחות'!$F$48),IF(11<=ROUND(1/(0.1*'נתונים והנחות'!$F$22),0),'נתונים והנחות'!$F$48*0.1*'נתונים והנחות'!$F$22,0),0) | R29: =IF(ISNUMBER('נתונים והנחות'!$F$48),IF(12<=ROUND(1/(0.1*'נתונים והנחות'!$F$22),0),'נתונים והנחות'!$F$48*0.1*'נתונים והנחות'!$F$22,0),0) | S29: =IF(ISNUMBER('נתונים והנחות'!$F$48),IF(13<=ROUND(1/(0.1*'נתונים והנחות'!$F$22),0),'נתונים והנחות'!$F$48*0.1*'נתונים והנחות'!$F$22,0),0) | T29: =IF(ISNUMBER('נתונים והנחות'!$F$48),IF(14<=ROUND(1/(0.1*'נתונים והנחות'!$F$22),0),'נתונים והנחות'!$F$48*0.1*'נתונים והנחות'!$F$22,0),0) | U29: =IF(ISNUMBER('נתונים והנחות'!$F$48),IF(15<=ROUND(1/(0.1*'נתונים והנחות'!$F$22),0),'נתונים והנחות'!$F$48*0.1*'נתונים והנחות'!$F$22,0),0) | V29: =IF(ISNUMBER('נתונים והנחות'!$F$48),IF(16<=ROUND(1/(0.1*'נתונים והנחות'!$F$22),0),'נתונים והנחות'!$F$48*0.1*'נתונים והנחות'!$F$22,0),0) | W29: =IF(ISNUMBER('נתונים והנחות'!$F$48),IF(17<=ROUND(1/(0.1*'נתונים והנחות'!$F$22),0),'נתונים והנחות'!$F$48*0.1*'נתונים והנחות'!$F$22,0),0) | X29: =IF(ISNUMBER('נתונים והנחות'!$F$48),IF(18<=ROUND(1/(0.1*'נתונים והנחות'!$F$22),0),'נתונים והנחות'!$F$48*0.1*'נתונים והנחות'!$F$22,0),0) | Y29: =IF(ISNUMBER('נתונים והנחות'!$F$48),IF(19<=ROUND(1/(0.1*'נתונים והנחות'!$F$22),0),'נתונים והנחות'!$F$48*0.1*'נתונים והנחות'!$F$22,0),0) | Z29: =IF(ISNUMBER('נתונים והנחות'!$F$48),IF(20<=ROUND(1/(0.1*'נתונים והנחות'!$F$22),0),'נתונים והנחות'!$F$48*0.1*'נתונים והנחות'!$F$22,0),0)
B30: מגן מס מואץ — משאבות חום (חימום מים) | C30: ₪ | D30: חישוב | E30: =פחת מואץ × שיעור מס | F30: 0 | G30: =G29*'נתונים והנחות'!$F$10 | H30: =H29*'נתונים והנחות'!$F$10 | I30: =I29*'נתונים והנחות'!$F$10 | J30: =J29*'נתונים והנחות'!$F$10 | K30: =K29*'נתונים והנחות'!$F$10 | L30: =L29*'נתונים והנחות'!$F$10 | M30: =M29*'נתונים והנחות'!$F$10 | N30: =N29*'נתונים והנחות'!$F$10 | ... Z30: =Z29*'נתונים והנחות'!$F$10
B32: ג. ניתוח תזרים מזומנים — שלושה תרחישים
B33: פרמטר | C33: יחידות | D33: מקור | E33: הערות | F33: שנה 0 (השקעה) | G33: שנה 1 | H33: שנה 2 | I33: שנה 3 | J33: שנה 4 | K33: שנה 5 | L33: שנה 6 | M33: שנה 7 | N33: שנה 8 | O33: שנה 9 | P33: שנה 10 | Q33: שנה 11 | R33: שנה 12 | S33: שנה 13 | T33: שנה 14 | U33: שנה 15 | V33: שנה 16 | W33: שנה 17 | X33: שנה 18 | Y33: שנה 19 | Z33: שנה 20
B34: תרחיש A — רכישת תנור מזוט/סולר (ציוד קיים / לא יעיל)
B35: השקעה ראשונית | C35: ₪ | D35: חישוב | F35: =IF(ISNUMBER('נתונים והנחות'!$F$47),-'נתונים והנחות'!$F$47,"PENDING")
B36: OPEX אנרגיה | C36: ₪ | D36: חישוב | F36: 0 | G36: =IF(ISNUMBER('נתונים והנחות'!$F$55),-'נתונים והנחות'!$F$55,0) | H36: =IF(ISNUMBER('נתונים והנחות'!$F$55),-'נתונים והנחות'!$F$55,0) | I36: =IF(ISNUMBER('נתונים והנחות'!$F$55),-'נתונים והנחות'!$F$55,0) | J36: =IF(ISNUMBER('נתונים והנחות'!$F$55),-'נתונים והנחות'!$F$55,0) | K36: =IF(ISNUMBER('נתונים והנחות'!$F$55),-'נתונים והנחות'!$F$55,0) | L36: =IF(ISNUMBER('נתונים והנחות'!$F$55),-'נתונים והנחות'!$F$55,0) | M36: =IF(ISNUMBER('נתונים והנחות'!$F$55),-'נתונים והנחות'!$F$55,0) | N36: =IF(ISNUMBER('נתונים והנחות'!$F$55),-'נתונים והנחות'!$F$55,0) | ... U36: =IF(ISNUMBER('נתונים והנחות'!$F$55),-'נתונים והנחות'!$F$55,0) | V36: =0 | W36: =0 | X36: =0 | Y36: =0 | Z36: =0
B37: OPEX אחר (תחזוקה וכו') | C37: ₪ | D37: חישוב | F37: 0 | G37: =IF(ISNUMBER('נתונים והנחות'!$F$53),-'נתונים והנחות'!$F$53,0) | H37: =IF(ISNUMBER('נתונים והנחות'!$F$53),-'נתונים והנחות'!$F$53,0) | I37: =IF(ISNUMBER('נתונים והנחות'!$F$53),-'נתונים והנחות'!$F$53,0) | J37: =IF(ISNUMBER('נתונים והנחות'!$F$53),-'נתונים והנחות'!$F$53,0) | K37: =IF(ISNUMBER('נתונים והנחות'!$F$53),-'נתונים והנחות'!$F$53,0) | L37: =IF(ISNUMBER('נתונים והנחות'!$F$53),-'נתונים והנחות'!$F$53,0) | M37: =IF(ISNUMBER('נתונים והנחות'!$F$53),-'נתונים והנחות'!$F$53,0) | N37: =IF(ISNUMBER('נתונים והנחות'!$F$53),-'נתונים והנחות'!$F$53,0) | ... U37: =IF(ISNUMBER('נתונים והנחות'!$F$53),-'נתונים והנחות'!$F$53,0) | V37: =0 | W37: =0 | X37: =0 | Y37: =0 | Z37: =0
B38: תזרים נקי — תרחיש A | C38: ₪ | D38: חישוב | F38: =F35 | G38: =G36+G37+G26 | H38: =H36+H37+H26 | I38: =I36+I37+I26 | J38: =J36+J37+J26 | K38: =K36+K37+K26 | L38: =L36+L37+L26 | M38: =M36+M37+M26 | N38: =N36+N37+N26 | ... Z38: =Z36+Z37+Z26
B39: תזרים מהוון — תרחיש A | C39: ₪ | D39: חישוב | F39: =F38 | G39: =G38/(1+'נתונים והנחות'!$F$11)^1 | H39: =H38/(1+'נתונים והנחות'!$F$11)^2 | I39: =I38/(1+'נתונים והנחות'!$F$11)^3 | J39: =J38/(1+'נתונים והנחות'!$F$11)^4 | K39: =K38/(1+'נתונים והנחות'!$F$11)^5 | L39: =L38/(1+'נתונים והנחות'!$F$11)^6 | M39: =M38/(1+'נתונים והנחות'!$F$11)^7 | N39: =N38/(1+'נתונים והנחות'!$F$11)^8 | O39: =O38/(1+'נתונים והנחות'!$F$11)^9 | P39: =P38/(1+'נתונים והנחות'!$F$11)^10 | Q39: =Q38/(1+'נתונים והנחות'!$F$11)^11 | R39: =R38/(1+'נתונים והנחות'!$F$11)^12 | S39: =S38/(1+'נתונים והנחות'!$F$11)^13 | T39: =T38/(1+'נתונים והנחות'!$F$11)^14 | U39: =U38/(1+'נתונים והנחות'!$F$11)^15 | V39: =V38/(1+'נתונים והנחות'!$F$11)^16 | W39: =W38/(1+'נתונים והנחות'!$F$11)^17 | X39: =X38/(1+'נתונים והנחות'!$F$11)^18 | Y39: =Y38/(1+'נתונים והנחות'!$F$11)^19 | Z39: =Z38/(1+'נתונים והנחות'!$F$11)^20
B40: NPV מצטבר — תרחיש A | C40: ₪ | D40: חישוב | F40: =F39 | G40: =F40+G39 | H40: =G40+H39 | I40: =H40+I39 | J40: =I40+J39 | K40: =J40+K39 | L40: =K40+L39 | M40: =L40+M39 | N40: =M40+N39 | ... Z40: =Y40+Z39
B42: תרחיש B — רכישת משאבות חום (חימום מים) | פחת סטנדרטי (ללא תמריץ)
B43: השקעה ראשונית | C43: ₪ | D43: חישוב | F43: =IF(ISNUMBER('נתונים והנחות'!$F$48),-'נתונים והנחות'!$F$48,"PENDING")
B44: OPEX אנרגיה (עם שחיקה שנתית) | C44: ₪ | D44: חישוב | F44: 0 | G44: =IF(ISNUMBER('נתונים והנחות'!$F$56),-'נתונים והנחות'!$F$56*(1-'נתונים והנחות'!$F$52)^0,0) | H44: =IF(ISNUMBER('נתונים והנחות'!$F$56),-'נתונים והנחות'!$F$56*(1-'נתונים והנחות'!$F$52)^1,0) | I44: =IF(ISNUMBER('נתונים והנחות'!$F$56),-'נתונים והנחות'!$F$56*(1-'נתונים והנחות'!$F$52)^2,0) | J44: =IF(ISNUMBER('נתונים והנחות'!$F$56),-'נתונים והנחות'!$F$56*(1-'נתונים והנחות'!$F$52)^3,0) | K44: =IF(ISNUMBER('נתונים והנחות'!$F$56),-'נתונים והנחות'!$F$56*(1-'נתונים והנחות'!$F$52)^4,0) | L44: =IF(ISNUMBER('נתונים והנחות'!$F$56),-'נתונים והנחות'!$F$56*(1-'נתונים והנחות'!$F$52)^5,0) | M44: =IF(ISNUMBER('נתונים והנחות'!$F$56),-'נתונים והנחות'!$F$56*(1-'נתונים והנחות'!$F$52)^6,0) | N44: =IF(ISNUMBER('נתונים והנחות'!$F$56),-'נתונים והנחות'!$F$56*(1-'נתונים והנחות'!$F$52)^7,0) | O44: =IF(ISNUMBER('נתונים והנחות'!$F$56),-'נתונים והנחות'!$F$56*(1-'נתונים והנחות'!$F$52)^8,0) | P44: =IF(ISNUMBER('נתונים והנחות'!$F$56),-'נתונים והנחות'!$F$56*(1-'נתונים והנחות'!$F$52)^9,0) | Q44: =0 | R44: =0 | S44: =0 | T44: =0 | U44: =0 | V44: =0 | W44: =0 | X44: =0 | ... Z44: =0
B45: OPEX אחר (תחזוקה וכו') | C45: ₪ | D45: חישוב | F45: 0 | G45: =IF(ISNUMBER('נתונים והנחות'!$F$54),-'נתונים והנחות'!$F$54,0) | H45: =IF(ISNUMBER('נתונים והנחות'!$F$54),-'נתונים והנחות'!$F$54,0) | I45: =IF(ISNUMBER('נתונים והנחות'!$F$54),-'נתונים והנחות'!$F$54,0) | J45: =IF(ISNUMBER('נתונים והנחות'!$F$54),-'נתונים והנחות'!$F$54,0) | K45: =IF(ISNUMBER('נתונים והנחות'!$F$54),-'נתונים והנחות'!$F$54,0) | L45: =IF(ISNUMBER('נתונים והנחות'!$F$54),-'נתונים והנחות'!$F$54,0) | M45: =IF(ISNUMBER('נתונים והנחות'!$F$54),-'נתונים והנחות'!$F$54,0) | N45: =IF(ISNUMBER('נתונים והנחות'!$F$54),-'נתונים והנחות'!$F$54,0) | ... P45: =IF(ISNUMBER('נתונים והנחות'!$F$54),-'נתונים והנחות'!$F$54,0) | Q45: =0 | R45: =0 | S45: =0 | T45: =0 | U45: =0 | V45: =0 | W45: =0 | X45: =0 | ... Z45: =0
...
