Workbook

Sheet נתונים והנחות - כללי
B1: מקרא צבעים
B2: ערך להזנה
B3: נתונים לעדכון / בקרה
B4: כותרות משנה
B5: תוצאת חישוב / טקסט
B6: תוצאות
B7: שורת תמריץ
B9: 1. פרמטרים פיננסיים
B10: שיעור מס חברות | C10: % | D10: רשות המסים | F10: 0.23
B11: שיעור היוון - יזמי / פרטי | C11: % | D11: הנחת עבודה | E11: 6% לאומי / 10% תעשייתי — ממתין להחלטת דניאל | F11: 0.1
B12: מחיר חשמל ממוצע לתעשייה | C12: אג׳/קוט"ש | D12: חברת החשמל | E12: ממוצע SMP 2024 | F12: 14
B14: 2. שיעורי פחת סטנדרטיים לפי תקנות מס הכנסה
B15: משאבות חום | C15: % לשנה | D15: תקנות פחת | E15: ציוד מכני | F15: 0.1
B16: צ'ילרים ומערכות קירור | C16: % לשנה | D16: תקנות פחת | E16: ציוד מכני | F16: 0.1
B17: מדחסי VSD | C17: % לשנה | D17: תקנות פחת | E17: ציוד מכני | F17: 0.1
B18: מערכות קיטור | C18: % לשנה | D18: תקנות פחת | E18: ציוד מכני | F18: 0.1
B20: * שיעורי הפחת לעיל הם הנחות עבודה — יש לוודא מול יועץ מס לפני הגשה

Sheet פרמטרי תמריץ
B1: מקרא צבעים
B2: ערך להזנה
B3: נתונים לעדכון / בקרה
B4: כותרות משנה
B5: תוצאת חישוב / טקסט
B6: תוצאות
B7: שורת תמריץ
B8: פרמטרי פחת מואץ — מדיניות
B9: שנה את הערך בתא F10 כדי לשנות את שיעור הפחת המואץ בשנה הראשונה. הערך מוזן פעם אחת כאן ומשפיע על כל ארבעת הניתוחים.
B10: שיעור פחת מואץ בשנה 1 ← פרמטר המדיניות המרכזי | C10: % | D10: פרמטר ניתן לשינוי | E10: 0% = ללא תמריץ | 100% = מחיקה מלאה בשנה 1 (מודל אירלנד / קנדה / סינגפור) | F10: 1
B12: 2. תרחישים לדוגמא — דגמים בינלאומיים
B13: אירלנד ACA / קנדה AII / סינגפור s.19A | C13: 100% | D13: מחיקה מלאה בשנה 1
B14: ספרד — פחת חופשי | C14: 100% | D14: עד 500K EUR, 2023–2024 בלבד
B15: קפריסין — מכפיל 2× (אנרגיה סולארית) | C15: מכפיל | D15: 200% מהפחת הרגיל
B16: תרחיש 3 שנים | C16: 33% | D16: פריסה שווה — שנה 1–3
B17: תרחיש 5 שנים | C17: 20% | D17: פריסה שווה — שנה 1–5
B18: ללא תמריץ (סטנדרטי) | C18: 0% | D18: פחת לפי אורך חיי הציוד (10% לשנה)
B20: * שנה 2 ואילך: יתרת עלות הרכישה (CapEx × (1 − שיעור מואץ)) מופחתת בקו ישר על יתרת שנות אורך החיים הרגיל

Sheet ניתוח - משאבות חום
B1: מקרא צבעים
B2: ערך להזנה
B3: נתונים לעדכון / בקרה
B4: כותרות משנה
B5: תוצאת חישוב / טקסט
B6: תוצאות
B7: שורת תמריץ
B8: ניתוח כלכלי — משאבות חום (חימום מים)
B9: * החלפת דוד חשמל במשאבת חום | חיסכון ~50% מצריכה
B11: 1. הנחות בסיסיות להשקעה
B12: עלות השקעה (CapEx) | C12: ₪ | D12: נתוני רפי | E12: ⚠ ממתין לנתוני ראש המהנדסים | F12: PENDING
B13: צריכת אנרגיה שנתית (לפני החלפה) | C13: קוט"ש/שנה | D13: נתוני רפי | E13: ⚠ ממתין לנתוני ראש המהנדסים | F13: PENDING
B14: חיסכון אנרגטי | C14: % מצריכה | D14: ממצאי הנדסה | F14: 0.5
B15: חיסכון שנתי בצריכת חשמל | C15: קוט"ש/שנה | D15: חישוב | E15: =צריכה × שיעור חיסכון | F15: =IF(ISNUMBER($F$13),$F$13*$F$14,"PENDING")
B16: אורך חיי הציוד (כלכלי) | C16: שנים | D16: ממצאי הנדסה | F16: 10
B17: מחיר חשמל | C17: ₪/קוט"ש | D17: גיליון הנחות | F17: ='נתונים והנחות - כללי'!$F$12/100
B18: חיסכון שנתי (₪) | C18: ₪/שנה | D18: חישוב | E18: =חיסכון קוט"ש × מחיר חשמל | F18: =IF(ISNUMBER($F$15),$F$15*$F$17,"PENDING")
B20: 2. הנחות פיננסיות
B21: שיעור מס חברות | C21: % | D21: גיליון הנחות | F21: ='נתונים והנחות - כללי'!$F$10
B22: שיעור היוון | C22: % | D22: גיליון הנחות | F22: ='נתונים והנחות - כללי'!$F$11
B23: שיעור פחת סטנדרטי | C23: %/שנה | D23: תקנות מס הכנסה | E23: קו ישר — 10 שנים | F23: 0.1
B25: 3. פרמטר המדיניות — פחת מואץ
B26: שיעור פחת מואץ בשנה 1 ← שנה ב'פרמטרי תמריץ'!F10 | C26: % מה-CapEx | D26: פרמטרי תמריץ | E26: 0% = ללא תמריץ (פחת סטנדרטי) | 100% = מחיקה מלאה בשנה 1 | F26: ='פרמטרי תמריץ'!$F$10
B28: 4. לוחות פחת — השוואה
B29: פרמטר | C29: יחידות | D29: מקור | E29: הערות | F29: שנה 0 (השקעה) | G29: שנה 1 | H29: שנה 2 | I29: שנה 3 | J29: שנה 4 | K29: שנה 5 | L29: שנה 6 | M29: שנה 7 | N29: שנה 8 | O29: שנה 9 | P29: שנה 10 | Q29: שנה 11 | R29: שנה 12 | S29: שנה 13 | T29: שנה 14 | U29: שנה 15 | V29: שנה 16 | W29: שנה 17 | X29: שנה 18 | Y29: שנה 19 | Z29: שנה 20
B30: פחת שנתי — סטנדרטי | C30: ₪ | D30: חישוב | E30: =CapEx × 10% | קו ישר | עד שנה 10 | F30: 0 | G30: =IF(ISNUMBER($F$12),$F$12*$F$23,0) | H30: =IF(ISNUMBER($F$12),$F$12*$F$23,0) | I30: =IF(ISNUMBER($F$12),$F$12*$F$23,0) | J30: =IF(ISNUMBER($F$12),$F$12*$F$23,0) | K30: =IF(ISNUMBER($F$12),$F$12*$F$23,0) | L30: =IF(ISNUMBER($F$12),$F$12*$F$23,0) | M30: =IF(ISNUMBER($F$12),$F$12*$F$23,0) | N30: =IF(ISNUMBER($F$12),$F$12*$F$23,0) | ... P30: =IF(ISNUMBER($F$12),$F$12*$F$23,0) | Q30: =0 | R30: =0 | S30: =0 | T30: =0 | U30: =0 | V30: =0 | W30: =0 | X30: =0 | ... Z30: =0
B31: מגן מס — סטנדרטי | C31: ₪ | D31: חישוב | E31: =פחת × שיעור מס | F31: 0 | G31: =G30*$F$21 | H31: =H30*$F$21 | I31: =I30*$F$21 | J31: =J30*$F$21 | K31: =K30*$F$21 | L31: =L30*$F$21 | M31: =M30*$F$21 | N31: =N30*$F$21 | ... Z31: =Z30*$F$21
B32: פחת שנתי — מואץ | C32: ₪ | D32: חישוב | E32: שנה 1 = CapEx × שיעור מואץ | יתרה מפוחתת בקו ישר | F32: 0 | G32: =IF(ISNUMBER($F$12),$F$12*$F$26,0) | H32: =IF(ISNUMBER($F$12),$F$12*(1-$F$26)/9,0) | I32: =IF(ISNUMBER($F$12),$F$12*(1-$F$26)/9,0) | J32: =IF(ISNUMBER($F$12),$F$12*(1-$F$26)/9,0) | K32: =IF(ISNUMBER($F$12),$F$12*(1-$F$26)/9,0) | L32: =IF(ISNUMBER($F$12),$F$12*(1-$F$26)/9,0) | M32: =IF(ISNUMBER($F$12),$F$12*(1-$F$26)/9,0) | N32: =IF(ISNUMBER($F$12),$F$12*(1-$F$26)/9,0) | O32: =IF(ISNUMBER($F$12),$F$12*(1-$F$26)/9,0) | P32: =IF(ISNUMBER($F$12),$F$12*(1-$F$26)/9,0) | Q32: =0 | R32: =0 | S32: =0 | T32: =0 | U32: =0 | V32: =0 | W32: =0 | X32: =0 | ... Z32: =0
B33: מגן מס — מואץ | C33: ₪ | D33: חישוב | E33: =פחת מואץ × שיעור מס | F33: 0 | G33: =G32*$F$21 | H33: =H32*$F$21 | I33: =I32*$F$21 | J33: =J32*$F$21 | K33: =K32*$F$21 | L33: =L32*$F$21 | M33: =M32*$F$21 | N33: =N32*$F$21 | ... Z33: =Z32*$F$21
B35: 5. ניתוח תזרים מזומנים
B36: פרמטר | C36: יחידות | D36: מקור | E36: הערות | F36: שנה 0 (השקעה) | G36: שנה 1 | H36: שנה 2 | I36: שנה 3 | J36: שנה 4 | K36: שנה 5 | L36: שנה 6 | M36: שנה 7 | N36: שנה 8 | O36: שנה 9 | P36: שנה 10 | Q36: שנה 11 | R36: שנה 12 | S36: שנה 13 | T36: שנה 14 | U36: שנה 15 | V36: שנה 16 | W36: שנה 17 | X36: שנה 18 | Y36: שנה 19 | Z36: שנה 20
B37: השקעה ראשונית (CapEx) | C37: ₪ | D37: חישוב | F37: =IF(ISNUMBER($F$12),-$F$12,"PENDING")
B38: חיסכון שנתי — אנרגיה | C38: ₪ | D38: חישוב | F38: 0 | G38: =IF(ISNUMBER($F$18),$F$18,0) | H38: =IF(ISNUMBER($F$18),$F$18,0) | I38: =IF(ISNUMBER($F$18),$F$18,0) | J38: =IF(ISNUMBER($F$18),$F$18,0) | K38: =IF(ISNUMBER($F$18),$F$18,0) | L38: =IF(ISNUMBER($F$18),$F$18,0) | M38: =IF(ISNUMBER($F$18),$F$18,0) | N38: =IF(ISNUMBER($F$18),$F$18,0) | ... P38: =IF(ISNUMBER($F$18),$F$18,0) | Q38: =0 | R38: =0 | S38: =0 | T38: =0 | U38: =0 | V38: =0 | W38: =0 | X38: =0 | ... Z38: =0
B39: תזרים נקי — ללא תמריץ | C39: ₪ | D39: חישוב | F39: 0 | G39: =G38+G31 | H39: =H38+H31 | I39: =I38+I31 | J39: =J38+J31 | K39: =K38+K31 | L39: =L38+L31 | M39: =M38+M31 | N39: =N38+N31 | ... Z39: =Z38+Z31
B40: תזרים מהוון — ללא תמריץ | C40: ₪ | D40: חישוב | F40: =F39 | G40: =G39/(1+$F$22)^1 | H40: =H39/(1+$F$22)^2 | I40: =I39/(1+$F$22)^3 | J40: =J39/(1+$F$22)^4 | K40: =K39/(1+$F$22)^5 | L40: =L39/(1+$F$22)^6 | M40: =M39/(1+$F$22)^7 | N40: =N39/(1+$F$22)^8 | O40: =O39/(1+$F$22)^9 | P40: =P39/(1+$F$22)^10 | Q40: =Q39/(1+$F$22)^11 | R40: =R39/(1+$F$22)^12 | S40: =S39/(1+$F$22)^13 | T40: =T39/(1+$F$22)^14 | U40: =U39/(1+$F$22)^15 | V40: =V39/(1+$F$22)^16 | W40: =W39/(1+$F$22)^17 | X40: =X39/(1+$F$22)^18 | Y40: =Y39/(1+$F$22)^19 | Z40: =Z39/(1+$F$22)^20
B41: NPV מצטבר — ללא תמריץ | C41: ₪ | D41: חישוב | F41: =F40 | G41: =F41+G40 | H41: =G41+H40 | I41: =H41+I40 | J41: =I41+J40 | K41: =J41+K40 | L41: =K41+L40 | M41: =L41+M40 | N41: =M41+N40 | ... Z41: =Y41+Z40
B42: תזרים נקי — עם תמריץ | C42: ₪ | D42: חישוב | F42: 0 | G42: =G38+G33 | H42: =H38+H33 | I42: =I38+I33 | J42: =J38+J33 | K42: =K38+K33 | L42: =L38+L33 | M42: =M38+M33 | N42: =N38+N33 | ... Z42: =Z38+Z33
B43: תזרים מהוון — עם תמריץ | C43: ₪ | D43: חישוב | F43: =F42 | G43: =G42/(1+$F$22)^1 | H43: =H42/(1+$F$22)^2 | I43: =I42/(1+$F$22)^3 | J43: =J42/(1+$F$22)^4 | K43: =K42/(1+$F$22)^5 | L43: =L42/(1+$F$22)^6 | M43: =M42/(1+$F$22)^7 | N43: =N42/(1+$F$22)^8 | O43: =O42/(1+$F$22)^9 | P43: =P42/(1+$F$22)^10 | Q43: =Q42/(1+$F$22)^11 | R43: =R42/(1+$F$22)^12 | S43: =S42/(1+$F$22)^13 | T43: =T42/(1+$F$22)^14 | U43: =U42/(1+$F$22)^15 | V43: =V42/(1+$F$22)^16 | W43: =W42/(1+$F$22)^17 | X43: =X42/(1+$F$22)^18 | Y43: =Y42/(1+$F$22)^19 | Z43: =Z42/(1+$F$22)^20
B44: NPV מצטבר — עם תמריץ | C44: ₪ | D44: חישוב | F44: =F43 | G44: =F44+G43 | H44: =G44+H43 | I44: =H44+I43 | J44: =I44+J43 | K44: =J44+K43 | L44: =K44+L43 | M44: =L44+M43 | N44: =M44+N43 | ... Z44: =Y44+Z43
B46: 6. תוצאות
...

Sheet ניתוח - צ'ילרים
B1: מקרא צבעים
B2: ערך להזנה
B3: נתונים לעדכון / בקרה
B4: כותרות משנה
B5: תוצאת חישוב / טקסט
B6: תוצאות
B7: שורת תמריץ
B8: ניתוח כלכלי — צ'ילרים
B9: * שדרוג מערכת קירור תעשייתית | חיסכון ~20% | טווח: 15–20 שנה
B11: 1. הנחות בסיסיות להשקעה
B12: עלות השקעה (CapEx) | C12: ₪ | D12: נתוני רפי | E12: ⚠ ממתין לנתוני ראש המהנדסים | F12: PENDING
B13: צריכת אנרגיה שנתית (לפני החלפה) | C13: קוט"ש/שנה | D13: נתוני רפי | E13: ⚠ ממתין לנתוני ראש המהנדסים | F13: PENDING
B14: חיסכון אנרגטי | C14: % מצריכה | D14: ממצאי הנדסה | F14: 0.2
B15: חיסכון שנתי בצריכת חשמל | C15: קוט"ש/שנה | D15: חישוב | E15: =צריכה × שיעור חיסכון | F15: =IF(ISNUMBER($F$13),$F$13*$F$14,"PENDING")
B16: אורך חיי הציוד (כלכלי) | C16: שנים | D16: ממצאי הנדסה | F16: 17
B17: מחיר חשמל | C17: ₪/קוט"ש | D17: גיליון הנחות | F17: ='נתונים והנחות - כללי'!$F$12/100
B18: חיסכון שנתי (₪) | C18: ₪/שנה | D18: חישוב | E18: =חיסכון קוט"ש × מחיר חשמל | F18: =IF(ISNUMBER($F$15),$F$15*$F$17,"PENDING")
B20: 2. הנחות פיננסיות
B21: שיעור מס חברות | C21: % | D21: גיליון הנחות | F21: ='נתונים והנחות - כללי'!$F$10
B22: שיעור היוון | C22: % | D22: גיליון הנחות | F22: ='נתונים והנחות - כללי'!$F$11
B23: שיעור פחת סטנדרטי | C23: %/שנה | D23: תקנות מס הכנסה | E23: קו ישר — 10 שנים | F23: 0.1
B25: 3. פרמטר המדיניות — פחת מואץ
B26: שיעור פחת מואץ בשנה 1 ← שנה ב'פרמטרי תמריץ'!F10 | C26: % מה-CapEx | D26: פרמטרי תמריץ | E26: 0% = ללא תמריץ (פחת סטנדרטי) | 100% = מחיקה מלאה בשנה 1 | F26: ='פרמטרי תמריץ'!$F$10
B28: 4. לוחות פחת — השוואה
B29: פרמטר | C29: יחידות | D29: מקור | E29: הערות | F29: שנה 0 (השקעה) | G29: שנה 1 | H29: שנה 2 | I29: שנה 3 | J29: שנה 4 | K29: שנה 5 | L29: שנה 6 | M29: שנה 7 | N29: שנה 8 | O29: שנה 9 | P29: שנה 10 | Q29: שנה 11 | R29: שנה 12 | S29: שנה 13 | T29: שנה 14 | U29: שנה 15 | V29: שנה 16 | W29: שנה 17 | X29: שנה 18 | Y29: שנה 19 | Z29: שנה 20
B30: פחת שנתי — סטנדרטי | C30: ₪ | D30: חישוב | E30: =CapEx × 10% | קו ישר | עד שנה 10 | F30: 0 | G30: =IF(ISNUMBER($F$12),$F$12*$F$23,0) | H30: =IF(ISNUMBER($F$12),$F$12*$F$23,0) | I30: =IF(ISNUMBER($F$12),$F$12*$F$23,0) | J30: =IF(ISNUMBER($F$12),$F$12*$F$23,0) | K30: =IF(ISNUMBER($F$12),$F$12*$F$23,0) | L30: =IF(ISNUMBER($F$12),$F$12*$F$23,0) | M30: =IF(ISNUMBER($F$12),$F$12*$F$23,0) | N30: =IF(ISNUMBER($F$12),$F$12*$F$23,0) | ... P30: =IF(ISNUMBER($F$12),$F$12*$F$23,0) | Q30: =0 | R30: =0 | S30: =0 | T30: =0 | U30: =0 | V30: =0 | W30: =0 | X30: =0 | ... Z30: =0
B31: מגן מס — סטנדרטי | C31: ₪ | D31: חישוב | E31: =פחת × שיעור מס | F31: 0 | G31: =G30*$F$21 | H31: =H30*$F$21 | I31: =I30*$F$21 | J31: =J30*$F$21 | K31: =K30*$F$21 | L31: =L30*$F$21 | M31: =M30*$F$21 | N31: =N30*$F$21 | ... Z31: =Z30*$F$21
B32: פחת שנתי — מואץ | C32: ₪ | D32: חישוב | E32: שנה 1 = CapEx × שיעור מואץ | יתרה מפוחתת בקו ישר | F32: 0 | G32: =IF(ISNUMBER($F$12),$F$12*$F$26,0) | H32: =IF(ISNUMBER($F$12),$F$12*(1-$F$26)/9,0) | I32: =IF(ISNUMBER($F$12),$F$12*(1-$F$26)/9,0) | J32: =IF(ISNUMBER($F$12),$F$12*(1-$F$26)/9,0) | K32: =IF(ISNUMBER($F$12),$F$12*(1-$F$26)/9,0) | L32: =IF(ISNUMBER($F$12),$F$12*(1-$F$26)/9,0) | M32: =IF(ISNUMBER($F$12),$F$12*(1-$F$26)/9,0) | N32: =IF(ISNUMBER($F$12),$F$12*(1-$F$26)/9,0) | O32: =IF(ISNUMBER($F$12),$F$12*(1-$F$26)/9,0) | P32: =IF(ISNUMBER($F$12),$F$12*(1-$F$26)/9,0) | Q32: =0 | R32: =0 | S32: =0 | T32: =0 | U32: =0 | V32: =0 | W32: =0 | X32: =0 | ... Z32: =0
B33: מגן מס — מואץ | C33: ₪ | D33: חישוב | E33: =פחת מואץ × שיעור מס | F33: 0 | G33: =G32*$F$21 | H33: =H32*$F$21 | I33: =I32*$F$21 | J33: =J32*$F$21 | K33: =K32*$F$21 | L33: =L32*$F$21 | M33: =M32*$F$21 | N33: =N32*$F$21 | ... Z33: =Z32*$F$21
B35: 5. ניתוח תזרים מזומנים
B36: פרמטר | C36: יחידות | D36: מקור | E36: הערות | F36: שנה 0 (השקעה) | G36: שנה 1 | H36: שנה 2 | I36: שנה 3 | J36: שנה 4 | K36: שנה 5 | L36: שנה 6 | M36: שנה 7 | N36: שנה 8 | O36: שנה 9 | P36: שנה 10 | Q36: שנה 11 | R36: שנה 12 | S36: שנה 13 | T36: שנה 14 | U36: שנה 15 | V36: שנה 16 | W36: שנה 17 | X36: שנה 18 | Y36: שנה 19 | Z36: שנה 20
B37: השקעה ראשונית (CapEx) | C37: ₪ | D37: חישוב | F37: =IF(ISNUMBER($F$12),-$F$12,"PENDING")
B38: חיסכון שנתי — אנרגיה | C38: ₪ | D38: חישוב | F38: 0 | G38: =IF(ISNUMBER($F$18),$F$18,0) | H38: =IF(ISNUMBER($F$18),$F$18,0) | I38: =IF(ISNUMBER($F$18),$F$18,0) | J38: =IF(ISNUMBER($F$18),$F$18,0) | K38: =IF(ISNUMBER($F$18),$F$18,0) | L38: =IF(ISNUMBER($F$18),$F$18,0) | M38: =IF(ISNUMBER($F$18),$F$18,0) | N38: =IF(ISNUMBER($F$18),$F$18,0) | ... W38: =IF(ISNUMBER($F$18),$F$18,0) | X38: =0 | Y38: =0 | Z38: =0
B39: תזרים נקי — ללא תמריץ | C39: ₪ | D39: חישוב | F39: 0 | G39: =G38+G31 | H39: =H38+H31 | I39: =I38+I31 | J39: =J38+J31 | K39: =K38+K31 | L39: =L38+L31 | M39: =M38+M31 | N39: =N38+N31 | ... Z39: =Z38+Z31
B40: תזרים מהוון — ללא תמריץ | C40: ₪ | D40: חישוב | F40: =F39 | G40: =G39/(1+$F$22)^1 | H40: =H39/(1+$F$22)^2 | I40: =I39/(1+$F$22)^3 | J40: =J39/(1+$F$22)^4 | K40: =K39/(1+$F$22)^5 | L40: =L39/(1+$F$22)^6 | M40: =M39/(1+$F$22)^7 | N40: =N39/(1+$F$22)^8 | O40: =O39/(1+$F$22)^9 | P40: =P39/(1+$F$22)^10 | Q40: =Q39/(1+$F$22)^11 | R40: =R39/(1+$F$22)^12 | S40: =S39/(1+$F$22)^13 | T40: =T39/(1+$F$22)^14 | U40: =U39/(1+$F$22)^15 | V40: =V39/(1+$F$22)^16 | W40: =W39/(1+$F$22)^17 | X40: =X39/(1+$F$22)^18 | Y40: =Y39/(1+$F$22)^19 | Z40: =Z39/(1+$F$22)^20
B41: NPV מצטבר — ללא תמריץ | C41: ₪ | D41: חישוב | F41: =F40 | G41: =F41+G40 | H41: =G41+H40 | I41: =H41+I40 | J41: =I41+J40 | K41: =J41+K40 | L41: =K41+L40 | M41: =L41+M40 | N41: =M41+N40 | ... Z41: =Y41+Z40
B42: תזרים נקי — עם תמריץ | C42: ₪ | D42: חישוב | F42: 0 | G42: =G38+G33 | H42: =H38+H33 | I42: =I38+I33 | J42: =J38+J33 | K42: =K38+K33 | L42: =L38+L33 | M42: =M38+M33 | N42: =N38+N33 | ... Z42: =Z38+Z33
B43: תזרים מהוון — עם תמריץ | C43: ₪ | D43: חישוב | F43: =F42 | G43: =G42/(1+$F$22)^1 | H43: =H42/(1+$F$22)^2 | I43: =I42/(1+$F$22)^3 | J43: =J42/(1+$F$22)^4 | K43: =K42/(1+$F$22)^5 | L43: =L42/(1+$F$22)^6 | M43: =M42/(1+$F$22)^7 | N43: =N42/(1+$F$22)^8 | O43: =O42/(1+$F$22)^9 | P43: =P42/(1+$F$22)^10 | Q43: =Q42/(1+$F$22)^11 | R43: =R42/(1+$F$22)^12 | S43: =S42/(1+$F$22)^13 | T43: =T42/(1+$F$22)^14 | U43: =U42/(1+$F$22)^15 | V43: =V42/(1+$F$22)^16 | W43: =W42/(1+$F$22)^17 | X43: =X42/(1+$F$22)^18 | Y43: =Y42/(1+$F$22)^19 | Z43: =Z42/(1+$F$22)^20
B44: NPV מצטבר — עם תמריץ | C44: ₪ | D44: חישוב | F44: =F43 | G44: =F44+G43 | H44: =G44+H43 | I44: =H44+I43 | J44: =I44+J43 | K44: =J44+K43 | L44: =K44+L43 | M44: =L44+M43 | N44: =M44+N43 | ... Z44: =Y44+Z43
B46: 6. תוצאות
...

Sheet ניתוח - מדחסי VSD
B1: מקרא צבעים
B2: ערך להזנה
B3: נתונים לעדכון / בקרה
B4: כותרות משנה
B5: תוצאת חישוב / טקסט
B6: תוצאות
B7: שורת תמריץ
B8: ניתוח כלכלי — מדחסי VSD
B9: * מדחסי אוויר עם בקרת מהירות משתנה | חיסכון ~20% | טווח: 10–15 שנה
B11: 1. הנחות בסיסיות להשקעה
B12: עלות השקעה (CapEx) | C12: ₪ | D12: נתוני רפי | E12: ⚠ ממתין לנתוני ראש המהנדסים | F12: PENDING
B13: צריכת אנרגיה שנתית (לפני החלפה) | C13: קוט"ש/שנה | D13: נתוני רפי | E13: ⚠ ממתין לנתוני ראש המהנדסים | F13: PENDING
B14: חיסכון אנרגטי | C14: % מצריכה | D14: ממצאי הנדסה | F14: 0.2
B15: חיסכון שנתי בצריכת חשמל | C15: קוט"ש/שנה | D15: חישוב | E15: =צריכה × שיעור חיסכון | F15: =IF(ISNUMBER($F$13),$F$13*$F$14,"PENDING")
B16: אורך חיי הציוד (כלכלי) | C16: שנים | D16: ממצאי הנדסה | F16: 12
B17: מחיר חשמל | C17: ₪/קוט"ש | D17: גיליון הנחות | F17: ='נתונים והנחות - כללי'!$F$12/100
B18: חיסכון שנתי (₪) | C18: ₪/שנה | D18: חישוב | E18: =חיסכון קוט"ש × מחיר חשמל | F18: =IF(ISNUMBER($F$15),$F$15*$F$17,"PENDING")
B20: 2. הנחות פיננסיות
B21: שיעור מס חברות | C21: % | D21: גיליון הנחות | F21: ='נתונים והנחות - כללי'!$F$10
B22: שיעור היוון | C22: % | D22: גיליון הנחות | F22: ='נתונים והנחות - כללי'!$F$11
B23: שיעור פחת סטנדרטי | C23: %/שנה | D23: תקנות מס הכנסה | E23: קו ישר — 10 שנים | F23: 0.1
B25: 3. פרמטר המדיניות — פחת מואץ
B26: שיעור פחת מואץ בשנה 1 ← שנה ב'פרמטרי תמריץ'!F10 | C26: % מה-CapEx | D26: פרמטרי תמריץ | E26: 0% = ללא תמריץ (פחת סטנדרטי) | 100% = מחיקה מלאה בשנה 1 | F26: ='פרמטרי תמריץ'!$F$10
B28: 4. לוחות פחת — השוואה
B29: פרמטר | C29: יחידות | D29: מקור | E29: הערות | F29: שנה 0 (השקעה) | G29: שנה 1 | H29: שנה 2 | I29: שנה 3 | J29: שנה 4 | K29: שנה 5 | L29: שנה 6 | M29: שנה 7 | N29: שנה 8 | O29: שנה 9 | P29: שנה 10 | Q29: שנה 11 | R29: שנה 12 | S29: שנה 13 | T29: שנה 14 | U29: שנה 15 | V29: שנה 16 | W29: שנה 17 | X29: שנה 18 | Y29: שנה 19 | Z29: שנה 20
B30: פחת שנתי — סטנדרטי | C30: ₪ | D30: חישוב | E30: =CapEx × 10% | קו ישר | עד שנה 10 | F30: 0 | G30: =IF(ISNUMBER($F$12),$F$12*$F$23,0) | H30: =IF(ISNUMBER($F$12),$F$12*$F$23,0) | I30: =IF(ISNUMBER($F$12),$F$12*$F$23,0) | J30: =IF(ISNUMBER($F$12),$F$12*$F$23,0) | K30: =IF(ISNUMBER($F$12),$F$12*$F$23,0) | L30: =IF(ISNUMBER($F$12),$F$12*$F$23,0) | M30: =IF(ISNUMBER($F$12),$F$12*$F$23,0) | N30: =IF(ISNUMBER($F$12),$F$12*$F$23,0) | ... P30: =IF(ISNUMBER($F$12),$F$12*$F$23,0) | Q30: =0 | R30: =0 | S30: =0 | T30: =0 | U30: =0 | V30: =0 | W30: =0 | X30: =0 | ... Z30: =0
B31: מגן מס — סטנדרטי | C31: ₪ | D31: חישוב | E31: =פחת × שיעור מס | F31: 0 | G31: =G30*$F$21 | H31: =H30*$F$21 | I31: =I30*$F$21 | J31: =J30*$F$21 | K31: =K30*$F$21 | L31: =L30*$F$21 | M31: =M30*$F$21 | N31: =N30*$F$21 | ... Z31: =Z30*$F$21
B32: פחת שנתי — מואץ | C32: ₪ | D32: חישוב | E32: שנה 1 = CapEx × שיעור מואץ | יתרה מפוחתת בקו ישר | F32: 0 | G32: =IF(ISNUMBER($F$12),$F$12*$F$26,0) | H32: =IF(ISNUMBER($F$12),$F$12*(1-$F$26)/9,0) | I32: =IF(ISNUMBER($F$12),$F$12*(1-$F$26)/9,0) | J32: =IF(ISNUMBER($F$12),$F$12*(1-$F$26)/9,0) | K32: =IF(ISNUMBER($F$12),$F$12*(1-$F$26)/9,0) | L32: =IF(ISNUMBER($F$12),$F$12*(1-$F$26)/9,0) | M32: =IF(ISNUMBER($F$12),$F$12*(1-$F$26)/9,0) | N32: =IF(ISNUMBER($F$12),$F$12*(1-$F$26)/9,0) | O32: =IF(ISNUMBER($F$12),$F$12*(1-$F$26)/9,0) | P32: =IF(ISNUMBER($F$12),$F$12*(1-$F$26)/9,0) | Q32: =0 | R32: =0 | S32: =0 | T32: =0 | U32: =0 | V32: =0 | W32: =0 | X32: =0 | ... Z32: =0
B33: מגן מס — מואץ | C33: ₪ | D33: חישוב | E33: =פחת מואץ × שיעור מס | F33: 0 | G33: =G32*$F$21 | H33: =H32*$F$21 | I33: =I32*$F$21 | J33: =J32*$F$21 | K33: =K32*$F$21 | L33: =L32*$F$21 | M33: =M32*$F$21 | N33: =N32*$F$21 | ... Z33: =Z32*$F$21
B35: 5. ניתוח תזרים מזומנים
B36: פרמטר | C36: יחידות | D36: מקור | E36: הערות | F36: שנה 0 (השקעה) | G36: שנה 1 | H36: שנה 2 | I36: שנה 3 | J36: שנה 4 | K36: שנה 5 | L36: שנה 6 | M36: שנה 7 | N36: שנה 8 | O36: שנה 9 | P36: שנה 10 | Q36: שנה 11 | R36: שנה 12 | S36: שנה 13 | T36: שנה 14 | U36: שנה 15 | V36: שנה 16 | W36: שנה 17 | X36: שנה 18 | Y36: שנה 19 | Z36: שנה 20
B37: השקעה ראשונית (CapEx) | C37: ₪ | D37: חישוב | F37: =IF(ISNUMBER($F$12),-$F$12,"PENDING")
B38: חיסכון שנתי — אנרגיה | C38: ₪ | D38: חישוב | F38: 0 | G38: =IF(ISNUMBER($F$18),$F$18,0) | H38: =IF(ISNUMBER($F$18),$F$18,0) | I38: =IF(ISNUMBER($F$18),$F$18,0) | J38: =IF(ISNUMBER($F$18),$F$18,0) | K38: =IF(ISNUMBER($F$18),$F$18,0) | L38: =IF(ISNUMBER($F$18),$F$18,0) | M38: =IF(ISNUMBER($F$18),$F$18,0) | N38: =IF(ISNUMBER($F$18),$F$18,0) | ... R38: =IF(ISNUMBER($F$18),$F$18,0) | S38: =0 | T38: =0 | U38: =0 | V38: =0 | W38: =0 | X38: =0 | Y38: =0 | Z38: =0
B39: תזרים נקי — ללא תמריץ | C39: ₪ | D39: חישוב | F39: 0 | G39: =G38+G31 | H39: =H38+H31 | I39: =I38+I31 | J39: =J38+J31 | K39: =K38+K31 | L39: =L38+L31 | M39: =M38+M31 | N39: =N38+N31 | ... Z39: =Z38+Z31
B40: תזרים מהוון — ללא תמריץ | C40: ₪ | D40: חישוב | F40: =F39 | G40: =G39/(1+$F$22)^1 | H40: =H39/(1+$F$22)^2 | I40: =I39/(1+$F$22)^3 | J40: =J39/(1+$F$22)^4 | K40: =K39/(1+$F$22)^5 | L40: =L39/(1+$F$22)^6 | M40: =M39/(1+$F$22)^7 | N40: =N39/(1+$F$22)^8 | O40: =O39/(1+$F$22)^9 | P40: =P39/(1+$F$22)^10 | Q40: =Q39/(1+$F$22)^11 | R40: =R39/(1+$F$22)^12 | S40: =S39/(1+$F$22)^13 | T40: =T39/(1+$F$22)^14 | U40: =U39/(1+$F$22)^15 | V40: =V39/(1+$F$22)^16 | W40: =W39/(1+$F$22)^17 | X40: =X39/(1+$F$22)^18 | Y40: =Y39/(1+$F$22)^19 | Z40: =Z39/(1+$F$22)^20
B41: NPV מצטבר — ללא תמריץ | C41: ₪ | D41: חישוב | F41: =F40 | G41: =F41+G40 | H41: =G41+H40 | I41: =H41+I40 | J41: =I41+J40 | K41: =J41+K40 | L41: =K41+L40 | M41: =L41+M40 | N41: =M41+N40 | ... Z41: =Y41+Z40
B42: תזרים נקי — עם תמריץ | C42: ₪ | D42: חישוב | F42: 0 | G42: =G38+G33 | H42: =H38+H33 | I42: =I38+I33 | J42: =J38+J33 | K42: =K38+K33 | L42: =L38+L33 | M42: =M38+M33 | N42: =N38+N33 | ... Z42: =Z38+Z33
B43: תזרים מהוון — עם תמריץ | C43: ₪ | D43: חישוב | F43: =F42 | G43: =G42/(1+$F$22)^1 | H43: =H42/(1+$F$22)^2 | I43: =I42/(1+$F$22)^3 | J43: =J42/(1+$F$22)^4 | K43: =K42/(1+$F$22)^5 | L43: =L42/(1+$F$22)^6 | M43: =M42/(1+$F$22)^7 | N43: =N42/(1+$F$22)^8 | O43: =O42/(1+$F$22)^9 | P43: =P42/(1+$F$22)^10 | Q43: =Q42/(1+$F$22)^11 | R43: =R42/(1+$F$22)^12 | S43: =S42/(1+$F$22)^13 | T43: =T42/(1+$F$22)^14 | U43: =U42/(1+$F$22)^15 | V43: =V42/(1+$F$22)^16 | W43: =W42/(1+$F$22)^17 | X43: =X42/(1+$F$22)^18 | Y43: =Y42/(1+$F$22)^19 | Z43: =Z42/(1+$F$22)^20
B44: NPV מצטבר — עם תמריץ | C44: ₪ | D44: חישוב | F44: =F43 | G44: =F44+G43 | H44: =G44+H43 | I44: =H44+I43 | J44: =I44+J43 | K44: =J44+K43 | L44: =K44+L43 | M44: =L44+M43 | N44: =M44+N43 | ... Z44: =Y44+Z43
B46: 6. תוצאות
...

Sheet ניתוח - קיטור חשמלי
B1: מקרא צבעים
B2: ערך להזנה
B3: נתונים לעדכון / בקרה
B4: כותרות משנה
B5: תוצאת חישוב / טקסט
B6: תוצאות
B7: שורת תמריץ
B8: ניתוח כלכלי — מערכות קיטור חשמליות
B9: * החלפת קיטור מבוסס דלק בקיטור חשמלי | חיסכון ~50% מצריכה
B11: 1. הנחות בסיסיות להשקעה
B12: עלות השקעה (CapEx) | C12: ₪ | D12: נתוני רפי | E12: ⚠ ממתין לנתוני ראש המהנדסים | F12: PENDING
B13: צריכת אנרגיה שנתית (לפני החלפה) | C13: קוט"ש/שנה | D13: נתוני רפי | E13: ⚠ ממתין לנתוני ראש המהנדסים | F13: PENDING
B14: חיסכון אנרגטי | C14: % מצריכה | D14: ממצאי הנדסה | F14: 0.5
B15: חיסכון שנתי בצריכת חשמל | C15: קוט"ש/שנה | D15: חישוב | E15: =צריכה × שיעור חיסכון | F15: =IF(ISNUMBER($F$13),$F$13*$F$14,"PENDING")
B16: אורך חיי הציוד (כלכלי) | C16: שנים | D16: ממצאי הנדסה | F16: 10
B17: מחיר חשמל | C17: ₪/קוט"ש | D17: גיליון הנחות | F17: ='נתונים והנחות - כללי'!$F$12/100
B18: חיסכון שנתי (₪) | C18: ₪/שנה | D18: חישוב | E18: =חיסכון קוט"ש × מחיר חשמל | F18: =IF(ISNUMBER($F$15),$F$15*$F$17,"PENDING")
B20: 2. הנחות פיננסיות
B21: שיעור מס חברות | C21: % | D21: גיליון הנחות | F21: ='נתונים והנחות - כללי'!$F$10
B22: שיעור היוון | C22: % | D22: גיליון הנחות | F22: ='נתונים והנחות - כללי'!$F$11
B23: שיעור פחת סטנדרטי | C23: %/שנה | D23: תקנות מס הכנסה | E23: קו ישר — 10 שנים | F23: 0.1
B25: 3. פרמטר המדיניות — פחת מואץ
B26: שיעור פחת מואץ בשנה 1 ← שנה ב'פרמטרי תמריץ'!F10 | C26: % מה-CapEx | D26: פרמטרי תמריץ | E26: 0% = ללא תמריץ (פחת סטנדרטי) | 100% = מחיקה מלאה בשנה 1 | F26: ='פרמטרי תמריץ'!$F$10
B28: 4. לוחות פחת — השוואה
B29: פרמטר | C29: יחידות | D29: מקור | E29: הערות | F29: שנה 0 (השקעה) | G29: שנה 1 | H29: שנה 2 | I29: שנה 3 | J29: שנה 4 | K29: שנה 5 | L29: שנה 6 | M29: שנה 7 | N29: שנה 8 | O29: שנה 9 | P29: שנה 10 | Q29: שנה 11 | R29: שנה 12 | S29: שנה 13 | T29: שנה 14 | U29: שנה 15 | V29: שנה 16 | W29: שנה 17 | X29: שנה 18 | Y29: שנה 19 | Z29: שנה 20
B30: פחת שנתי — סטנדרטי | C30: ₪ | D30: חישוב | E30: =CapEx × 10% | קו ישר | עד שנה 10 | F30: 0 | G30: =IF(ISNUMBER($F$12),$F$12*$F$23,0) | H30: =IF(ISNUMBER($F$12),$F$12*$F$23,0) | I30: =IF(ISNUMBER($F$12),$F$12*$F$23,0) | J30: =IF(ISNUMBER($F$12),$F$12*$F$23,0) | K30: =IF(ISNUMBER($F$12),$F$12*$F$23,0) | L30: =IF(ISNUMBER($F$12),$F$12*$F$23,0) | M30: =IF(ISNUMBER($F$12),$F$12*$F$23,0) | N30: =IF(ISNUMBER($F$12),$F$12*$F$23,0) | ... P30: =IF(ISNUMBER($F$12),$F$12*$F$23,0) | Q30: =0 | R30: =0 | S30: =0 | T30: =0 | U30: =0 | V30: =0 | W30: =0 | X30: =0 | ... Z30: =0
B31: מגן מס — סטנדרטי | C31: ₪ | D31: חישוב | E31: =פחת × שיעור מס | F31: 0 | G31: =G30*$F$21 | H31: =H30*$F$21 | I31: =I30*$F$21 | J31: =J30*$F$21 | K31: =K30*$F$21 | L31: =L30*$F$21 | M31: =M30*$F$21 | N31: =N30*$F$21 | ... Z31: =Z30*$F$21
B32: פחת שנתי — מואץ | C32: ₪ | D32: חישוב | E32: שנה 1 = CapEx × שיעור מואץ | יתרה מפוחתת בקו ישר | F32: 0 | G32: =IF(ISNUMBER($F$12),$F$12*$F$26,0) | H32: =IF(ISNUMBER($F$12),$F$12*(1-$F$26)/9,0) | I32: =IF(ISNUMBER($F$12),$F$12*(1-$F$26)/9,0) | J32: =IF(ISNUMBER($F$12),$F$12*(1-$F$26)/9,0) | K32: =IF(ISNUMBER($F$12),$F$12*(1-$F$26)/9,0) | L32: =IF(ISNUMBER($F$12),$F$12*(1-$F$26)/9,0) | M32: =IF(ISNUMBER($F$12),$F$12*(1-$F$26)/9,0) | N32: =IF(ISNUMBER($F$12),$F$12*(1-$F$26)/9,0) | O32: =IF(ISNUMBER($F$12),$F$12*(1-$F$26)/9,0) | P32: =IF(ISNUMBER($F$12),$F$12*(1-$F$26)/9,0) | Q32: =0 | R32: =0 | S32: =0 | T32: =0 | U32: =0 | V32: =0 | W32: =0 | X32: =0 | ... Z32: =0
B33: מגן מס — מואץ | C33: ₪ | D33: חישוב | E33: =פחת מואץ × שיעור מס | F33: 0 | G33: =G32*$F$21 | H33: =H32*$F$21 | I33: =I32*$F$21 | J33: =J32*$F$21 | K33: =K32*$F$21 | L33: =L32*$F$21 | M33: =M32*$F$21 | N33: =N32*$F$21 | ... Z33: =Z32*$F$21
B35: 5. ניתוח תזרים מזומנים
B36: פרמטר | C36: יחידות | D36: מקור | E36: הערות | F36: שנה 0 (השקעה) | G36: שנה 1 | H36: שנה 2 | I36: שנה 3 | J36: שנה 4 | K36: שנה 5 | L36: שנה 6 | M36: שנה 7 | N36: שנה 8 | O36: שנה 9 | P36: שנה 10 | Q36: שנה 11 | R36: שנה 12 | S36: שנה 13 | T36: שנה 14 | U36: שנה 15 | V36: שנה 16 | W36: שנה 17 | X36: שנה 18 | Y36: שנה 19 | Z36: שנה 20
B37: השקעה ראשונית (CapEx) | C37: ₪ | D37: חישוב | F37: =IF(ISNUMBER($F$12),-$F$12,"PENDING")
B38: חיסכון שנתי — אנרגיה | C38: ₪ | D38: חישוב | F38: 0 | G38: =IF(ISNUMBER($F$18),$F$18,0) | H38: =IF(ISNUMBER($F$18),$F$18,0) | I38: =IF(ISNUMBER($F$18),$F$18,0) | J38: =IF(ISNUMBER($F$18),$F$18,0) | K38: =IF(ISNUMBER($F$18),$F$18,0) | L38: =IF(ISNUMBER($F$18),$F$18,0) | M38: =IF(ISNUMBER($F$18),$F$18,0) | N38: =IF(ISNUMBER($F$18),$F$18,0) | ... P38: =IF(ISNUMBER($F$18),$F$18,0) | Q38: =0 | R38: =0 | S38: =0 | T38: =0 | U38: =0 | V38: =0 | W38: =0 | X38: =0 | ... Z38: =0
B39: תזרים נקי — ללא תמריץ | C39: ₪ | D39: חישוב | F39: 0 | G39: =G38+G31 | H39: =H38+H31 | I39: =I38+I31 | J39: =J38+J31 | K39: =K38+K31 | L39: =L38+L31 | M39: =M38+M31 | N39: =N38+N31 | ... Z39: =Z38+Z31
B40: תזרים מהוון — ללא תמריץ | C40: ₪ | D40: חישוב | F40: =F39 | G40: =G39/(1+$F$22)^1 | H40: =H39/(1+$F$22)^2 | I40: =I39/(1+$F$22)^3 | J40: =J39/(1+$F$22)^4 | K40: =K39/(1+$F$22)^5 | L40: =L39/(1+$F$22)^6 | M40: =M39/(1+$F$22)^7 | N40: =N39/(1+$F$22)^8 | O40: =O39/(1+$F$22)^9 | P40: =P39/(1+$F$22)^10 | Q40: =Q39/(1+$F$22)^11 | R40: =R39/(1+$F$22)^12 | S40: =S39/(1+$F$22)^13 | T40: =T39/(1+$F$22)^14 | U40: =U39/(1+$F$22)^15 | V40: =V39/(1+$F$22)^16 | W40: =W39/(1+$F$22)^17 | X40: =X39/(1+$F$22)^18 | Y40: =Y39/(1+$F$22)^19 | Z40: =Z39/(1+$F$22)^20
B41: NPV מצטבר — ללא תמריץ | C41: ₪ | D41: חישוב | F41: =F40 | G41: =F41+G40 | H41: =G41+H40 | I41: =H41+I40 | J41: =I41+J40 | K41: =J41+K40 | L41: =K41+L40 | M41: =L41+M40 | N41: =M41+N40 | ... Z41: =Y41+Z40
B42: תזרים נקי — עם תמריץ | C42: ₪ | D42: חישוב | F42: 0 | G42: =G38+G33 | H42: =H38+H33 | I42: =I38+I33 | J42: =J38+J33 | K42: =K38+K33 | L42: =L38+L33 | M42: =M38+M33 | N42: =N38+N33 | ... Z42: =Z38+Z33
B43: תזרים מהוון — עם תמריץ | C43: ₪ | D43: חישוב | F43: =F42 | G43: =G42/(1+$F$22)^1 | H43: =H42/(1+$F$22)^2 | I43: =I42/(1+$F$22)^3 | J43: =J42/(1+$F$22)^4 | K43: =K42/(1+$F$22)^5 | L43: =L42/(1+$F$22)^6 | M43: =M42/(1+$F$22)^7 | N43: =N42/(1+$F$22)^8 | O43: =O42/(1+$F$22)^9 | P43: =P42/(1+$F$22)^10 | Q43: =Q42/(1+$F$22)^11 | R43: =R42/(1+$F$22)^12 | S43: =S42/(1+$F$22)^13 | T43: =T42/(1+$F$22)^14 | U43: =U42/(1+$F$22)^15 | V43: =V42/(1+$F$22)^16 | W43: =W42/(1+$F$22)^17 | X43: =X42/(1+$F$22)^18 | Y43: =Y42/(1+$F$22)^19 | Z43: =Z42/(1+$F$22)^20
B44: NPV מצטבר — עם תמריץ | C44: ₪ | D44: חישוב | F44: =F43 | G44: =F44+G43 | H44: =G44+H43 | I44: =H44+I43 | J44: =I44+J43 | K44: =J44+K43 | L44: =K44+L43 | M44: =L44+M43 | N44: =M44+N43 | ... Z44: =Y44+Z43
B46: 6. תוצאות
...

Sheet סיכום
B1: מקרא צבעים
B2: ערך להזנה
B3: נתונים לעדכון / בקרה
B4: כותרות משנה
B5: תוצאת חישוב / טקסט
B6: תוצאות
B7: שורת תמריץ
B8: סיכום — ניתוח פחת מואץ לפי טכנולוגיה
B9: * פרמטר המדיניות (שיעור פחת מואץ בשנה 1) = 'פרמטרי תמריץ'!F10 — שנה שם ותוצאות מתעדכנות אוטומטית
B10: טכנולוגיה | C10: NPV ללא תמריץ (₪) | D10: NPV עם תמריץ (₪) | E10: דלתא NPV (₪) | F10: ROI ללא תמריץ | G10: ROI עם תמריץ | H10: שיפור ROI | I10: תקופת החזר — ללא | J10: תקופת החזר — עם
B11: משאבות חום (חימום מים) | C11: ='ניתוח - משאבות חום'!$F$47 | D11: ='ניתוח - משאבות חום'!$F$48 | E11: ='ניתוח - משאבות חום'!$F$49 | F11: ='ניתוח - משאבות חום'!$F$51 | G11: ='ניתוח - משאבות חום'!$F$52 | H11: ='ניתוח - משאבות חום'!$F$53 | I11: ='ניתוח - משאבות חום'!$F$55 | J11: ='ניתוח - משאבות חום'!$F$56
B12: צ'ילרים | C12: ='ניתוח - צ'ילרים'!$F$47 | D12: ='ניתוח - צ'ילרים'!$F$48 | E12: ='ניתוח - צ'ילרים'!$F$49 | F12: ='ניתוח - צ'ילרים'!$F$51 | G12: ='ניתוח - צ'ילרים'!$F$52 | H12: ='ניתוח - צ'ילרים'!$F$53 | I12: ='ניתוח - צ'ילרים'!$F$55 | J12: ='ניתוח - צ'ילרים'!$F$56
B13: מדחסי VSD | C13: ='ניתוח - מדחסי VSD'!$F$47 | D13: ='ניתוח - מדחסי VSD'!$F$48 | E13: ='ניתוח - מדחסי VSD'!$F$49 | F13: ='ניתוח - מדחסי VSD'!$F$51 | G13: ='ניתוח - מדחסי VSD'!$F$52 | H13: ='ניתוח - מדחסי VSD'!$F$53 | I13: ='ניתוח - מדחסי VSD'!$F$55 | J13: ='ניתוח - מדחסי VSD'!$F$56
B14: מערכות קיטור חשמליות | C14: ='ניתוח - קיטור חשמלי'!$F$47 | D14: ='ניתוח - קיטור חשמלי'!$F$48 | E14: ='ניתוח - קיטור חשמלי'!$F$49 | F14: ='ניתוח - קיטור חשמלי'!$F$51 | G14: ='ניתוח - קיטור חשמלי'!$F$52 | H14: ='ניתוח - קיטור חשמלי'!$F$53 | I14: ='ניתוח - קיטור חשמלי'!$F$55 | J14: ='ניתוח - קיטור חשמלי'!$F$56
B16: ** CapEx וצריכת אנרגיה שנתית עדיין ממתינים לנתוני רפי — לאחר הזנתם כל התוצאות יתעדכנו אוטומטית.
