Workbook

Sheet נתונים והנחות
B1: מקרא צבעים
B2: ערך להזנה / ממתין לנתונים
B3: נתון לעדכון / בקרה
B4: נתון ממקור אמיתי
B5: נתון מוערך/נגזר (עם מקור)
B6: תרחיש A — טכנולוגיה קיימת
B7: תרחיש B — יעיל, ללא תמריץ
B8: תרחיש C — יעיל, עם תמריץ
B9: 1. פרמטרים פיננסיים
B10: שיעור מס חברות | C10: % | D10: רשות המסים | F10: 0.23
B11: שיעור היוון (יזמי / פרטי) | C11: % | D11: סוכם עם דניאל (2026-07-13) | E11: 6% — הוחלט עם דניאל | F11: 0.06
B12: מחיר חשמל ממוצע לתעשייה | C12: אג'/קוט"ש | D12: חברת החשמל — ממוצע SMP 2024 | E12: נתון כללי, ייתכן שיעודכן לממוצע משוקלל לפי שעות תעו"ז | F12: 14
B13: 1ב. מחירי דלקים ומקדמי המרה (עבור בסיס משאבות חום)
B14: מחיר סולר בתעשייה (בתוספת מרווח שיווק) | C14: ₪/ליטר | D14: משרד האנרגיה — מחירים תיאורטיים 2024 | E14: מרווח שיווק - 0.5 ₪ (מוסיף עמרי) | F14: 2.59368
B15: מחיר מזוט בתעשייה (בתוספת מרווח שיווק) | C15: ₪/טון | D15: משרד האנרגיה — מחירים תיאורטיים 2024 | E15: מרווח שיווק - 0.5 ₪ (מוסיף עמרי) | F15: 2344.72
B16: יחס קלורי — סולר | C16: טון דלק/MWh | D16: אקסל של עמרי (MRV) | F16: 0.085
B17: יחס קלורי — מזוט | C17: טון דלק/MWh | D17: אקסל של עמרי (MRV) | F17: 0.088
B18: צפיפות סולר | C18: ק"ג/ליטר | D18: אקסל של עמרי (MRV) | E18: להמרת טון סולר לליטר אם נבחר סולר כדלק בסיס | F18: 0.82
B19: 2. פרמטר תמריץ — מכפיל פחת (פחת מואץ)
B20: מכפיל שיעור הפחת ← פרמטר המדיניות המרכזי | C20: מכפיל | D20: פרמטר ניתן לשינוי | E20: 1.0 = ללא תמריץ | 2.0 = כפול, 5 שנים | 5.0 = 2 שנים | F20: 2
B21: 3. שיעורי פחת סטנדרטיים — תקנות מס הכנסה
B22: משאבות חום | C22: % לשנה | D22: תקנות פחת — ציוד מכני | F22: 0.1
B23: צ'ילרים | C23: % לשנה | D23: תקנות פחת — ציוד מכני | F23: 0.1
B24: מדחסי VSD | C24: % לשנה | D24: תקנות פחת — ציוד מכני | F24: 0.1
B25: 4. הנחות לפי טכנולוגיה — שתי נקודות קיבולת לכל טכנולוגיה
B26: פרמטר | C26: יחידות | D26: מקור | E26: הערות | F26: משאבות חום — 40 kW | G26: משאבות חום — 70 kW | H26: צ'ילרים — 100 RT | I26: צ'ילרים — 500 RT | J26: מדחסי VSD — 45 kW | K26: מדחסי VSD — 150 kW
F27: vs. תנור מזוט/סולר — 40 kW | G27: vs. תנור מזוט/סולר — 70 kW | H27: vs. מערכת קירור קונבנציונלית — 100 RT | I27: vs. מערכת קירור קונבנציונלית — 500 RT | J27: vs. מדחס מהירות קבועה — 45 kW | K27: vs. מדחס מהירות קבועה — 150 kW
B28: קיבולת מותקנת | C28: kW / RT | D28: baseline-technology-data.md | F28: 40 | G28: 70 | H28: 100 | I28: 500 | J28: 45 | K28: 150
B29: שעות פעילות שנתיות | C29: שעות/שנה | D29: ראו הערות לפי טכנולוגיה | E29: משאבות חום: ממתין לייעוץ מהנדס | צ'ילרים: 3,000 (מספר עבודה) | VSD: 6,400 (אמצע 6,000-6,800) | F29: PENDING | G29: PENDING | H29: 3000 | I29: 3000 | J29: 6400 | K29: 6400
B30: COP — משאבת חום (יעיל) | C30: יחס | D30: Sprsun — עמוד מפרט מוצר | E30: משאבות חום בלבד | F30: 4.13 | G30: 3.235
B31: יעילות בעירה — תנור בסיס | C31: % | D31: ASME PTC 4 (אמצע 80-88%) | E31: משאבות חום בלבד | F31: 0.835 | G31: 0.835
B32: סוג דלק בסיס | C32: טקסט | D32: הנחת עבודה — ניתן לשנות | E32: משאבות חום בלבד — "מזוט"/"סולר" | F32: סולר | G32: סולר
B33: יעילות אנרגטית — בסיסי | C33: kW/ton | kW/100cfm | D33: צ'ילר: ASHRAE 90.1 | VSD: CAGI | E33: צ'ילרים/VSD בלבד | H33: 0.95 | I33: 0.6 | J33: 21.5 | K33: 21.5
B34: יעילות אנרגטית — יעיל | C34: kW/ton | kW/100cfm | D34: צ'ילר: DOE FEMP | VSD: CAGI | E34: צ'ילרים/VSD בלבד | H34: 0.8 | I34: 0.48 | J34: 16.5 | K34: 16.5
B35: חיסכון אנרגטי (מחושב) | C35: % מצריכה | D35: חישוב | E35: צ'ילרים/VSD — נגזר משורות 33-34 | F35: - | G35: - | H35: =IF(AND(ISNUMBER(H33),ISNUMBER(H34)),(H33-H34)/H33,"PENDING") | I35: =IF(AND(ISNUMBER(I33),ISNUMBER(I34)),(I33-I34)/I33,"PENDING") | J35: =IF(AND(ISNUMBER(J33),ISNUMBER(J34)),(J33-J34)/J33,"PENDING") | K35: =IF(AND(ISNUMBER(K33),ISNUMBER(K34)),(K33-K34)/K33,"PENDING")
B36: צריכת אנרגיה/דלק שנתית — בסיסי | C36: טון דלק / קוט"ש | D36: חישוב — קיבולת × שעות × יעילות | E36: משאבות חום: טון דלק | אחר: קוט"ש | F36: =IF(AND(ISNUMBER(F28),ISNUMBER(F29),ISNUMBER(F31)),(F28*F29/1000/F31)*IF(F32="מזוט",'נתונים והנחות'!$F$17,'נתונים והנחות'!$F$16),"PENDING") | G36: =IF(AND(ISNUMBER(G28),ISNUMBER(G29),ISNUMBER(G31)),(G28*G29/1000/G31)*IF(G32="מזוט",'נתונים והנחות'!$F$17,'נתונים והנחות'!$F$16),"PENDING") | H36: =IF(AND(ISNUMBER(H28),ISNUMBER(H29),ISNUMBER(H33)),H28*H33*H29,"PENDING") | I36: =IF(AND(ISNUMBER(I28),ISNUMBER(I29),ISNUMBER(I33)),I28*I33*I29,"PENDING") | J36: =IF(AND(ISNUMBER(J28),ISNUMBER(J29)),J28*J29,"PENDING") | K36: =IF(AND(ISNUMBER(K28),ISNUMBER(K29)),K28*K29,"PENDING")
B37: צריכת חשמל שנתית — יעיל | C37: קוט"ש/שנה | D37: חישוב | E37: הצד היעיל תמיד חשמלי | F37: =IF(AND(ISNUMBER(F28),ISNUMBER(F29),ISNUMBER(F30)),F28*F29/F30,"PENDING") | G37: =IF(AND(ISNUMBER(G28),ISNUMBER(G29),ISNUMBER(G30)),G28*G29/G30,"PENDING") | H37: =IF(AND(ISNUMBER(H36),ISNUMBER(H35)),H36*(1-H35),"PENDING") | I37: =IF(AND(ISNUMBER(I36),ISNUMBER(I35)),I36*(1-I35),"PENDING") | J37: =IF(AND(ISNUMBER(J36),ISNUMBER(J35)),J36*(1-J35),"PENDING") | K37: =IF(AND(ISNUMBER(K36),ISNUMBER(K35)),K36*(1-K35),"PENDING")
B39: CapEx — ציוד קיים (בסיסי) | C39: ₪ | D39: ראו הערות לפי טכנולוגיה | E39: צ'ילר: יעיל ÷ 1.175 (פרמיית יעילות 10-25%) | VSD: יעיל ÷ 1.225 (פרמיית VSD 15-30%) | משאבות חום: אין מקור לתנור בסיס — ממתין | F39: PENDING | G39: PENDING | H39: 356200 | I39: 1781000 | J39: 55102 | K39: 183673
B40: CapEx — ציוד יעיל | C40: ₪ | D40: ראו הערות לפי טכנולוגיה | E40: משאבות חום: מענקים ₪1,050/kW | צ'ילר: מענקים חציון ₪4,186/טון | VSD: מענקים חציון ₪1,500/kW | F40: 42000 | G40: 73500 | H40: 418600 | I40: 2093000 | J40: 67500 | K40: 225000
B41: ΔCapEx = יעיל − בסיסי | C41: ₪ | D41: חישוב | F41: =IF(ISNUMBER(F40)*ISNUMBER(F39),F40-F39,"PENDING") | G41: =IF(ISNUMBER(G40)*ISNUMBER(G39),G40-G39,"PENDING") | H41: =IF(ISNUMBER(H40)*ISNUMBER(H39),H40-H39,"PENDING") | I41: =IF(ISNUMBER(I40)*ISNUMBER(I39),I40-I39,"PENDING") | J41: =IF(ISNUMBER(J40)*ISNUMBER(J39),J40-J39,"PENDING") | K41: =IF(ISNUMBER(K40)*ISNUMBER(K39),K40-K39,"PENDING")
...

Sheet ניתוח
B1: מקרא צבעים
B2: ערך להזנה / ממתין לנתונים
B3: נתון לעדכון / בקרה
B4: נתון ממקור אמיתי
B5: נתון מוערך/נגזר (עם מקור)
B6: תרחיש A — טכנולוגיה קיימת
B7: תרחיש B — יעיל, ללא תמריץ
B8: תרחיש C — יעיל, עם תמריץ
B9: ניתוח כלכלי — פחת מואץ לפי טכנולוגיה | NPV בלבד
B11: 1. פרמטרים פיננסיים
B12: שיעור מס חברות | C12: % | D12: נתונים והנחות | F12: ='נתונים והנחות'!$F$10
B13: שיעור היוון | C13: % | D13: נתונים והנחות | F13: ='נתונים והנחות'!$F$11
B14: מחיר חשמל (₪/קוט"ש) | C14: ₪/קוט"ש | D14: נתונים והנחות | F14: ='נתונים והנחות'!$F$12/100
B16: 2. פרמטר תמריץ — מכפיל פחת
B17: מכפיל שיעור הפחת ← שנה ב'נתונים והנחות'!F20 | C17: מכפיל | D17: נתונים והנחות | F17: ='נתונים והנחות'!$F$20
B19: 3. ניתוחים לפי טכנולוגיה
B21: 3.1א משאבות חום — 40 kW
B22: * מול תנור מזוט/סולר — 40 kW | נתונים: גיליון 'נתונים והנחות' סעיף 4
B23: ב. לוחות פחת (ציוד בסיסי vs. יעיל)
B24: פרמטר | C24: יחידות | D24: מקור | E24: הערות | F24: שנה 0 (השקעה) | G24: שנה 1 | H24: שנה 2 | I24: שנה 3 | J24: שנה 4 | K24: שנה 5 | L24: שנה 6 | M24: שנה 7 | N24: שנה 8 | O24: שנה 9 | P24: שנה 10 | Q24: שנה 11 | R24: שנה 12 | S24: שנה 13 | T24: שנה 14 | U24: שנה 15 | V24: שנה 16 | W24: שנה 17 | X24: שנה 18 | Y24: שנה 19 | Z24: שנה 20
B25: פחת סטנדרטי — תנור מזוט/סולר — 40 kW | C25: ₪ | D25: חישוב | F25: 0 | G25: =IF(ISNUMBER('נתונים והנחות'!$F$39),'נתונים והנחות'!$F$39*0.1,0) | H25: =IF(ISNUMBER('נתונים והנחות'!$F$39),'נתונים והנחות'!$F$39*0.1,0) | I25: =IF(ISNUMBER('נתונים והנחות'!$F$39),'נתונים והנחות'!$F$39*0.1,0) | J25: =IF(ISNUMBER('נתונים והנחות'!$F$39),'נתונים והנחות'!$F$39*0.1,0) | K25: =IF(ISNUMBER('נתונים והנחות'!$F$39),'נתונים והנחות'!$F$39*0.1,0) | L25: =IF(ISNUMBER('נתונים והנחות'!$F$39),'נתונים והנחות'!$F$39*0.1,0) | M25: =IF(ISNUMBER('נתונים והנחות'!$F$39),'נתונים והנחות'!$F$39*0.1,0) | N25: =IF(ISNUMBER('נתונים והנחות'!$F$39),'נתונים והנחות'!$F$39*0.1,0) | ... P25: =IF(ISNUMBER('נתונים והנחות'!$F$39),'נתונים והנחות'!$F$39*0.1,0) | Q25: =0 | R25: =0 | S25: =0 | T25: =0 | U25: =0 | V25: =0 | W25: =0 | X25: =0 | ... Z25: =0
B26: מגן מס — תנור מזוט/סולר — 40 kW | C26: ₪ | D26: חישוב | F26: 0 | G26: =G25*'נתונים והנחות'!$F$10 | H26: =H25*'נתונים והנחות'!$F$10 | I26: =I25*'נתונים והנחות'!$F$10 | J26: =J25*'נתונים והנחות'!$F$10 | K26: =K25*'נתונים והנחות'!$F$10 | L26: =L25*'נתונים והנחות'!$F$10 | M26: =M25*'נתונים והנחות'!$F$10 | N26: =N25*'נתונים והנחות'!$F$10 | ... Z26: =Z25*'נתונים והנחות'!$F$10
B27: פחת סטנדרטי — משאבות חום — 40 kW | C27: ₪ | D27: חישוב | F27: 0 | G27: =IF(ISNUMBER('נתונים והנחות'!$F$40),'נתונים והנחות'!$F$40*0.1,0) | H27: =IF(ISNUMBER('נתונים והנחות'!$F$40),'נתונים והנחות'!$F$40*0.1,0) | I27: =IF(ISNUMBER('נתונים והנחות'!$F$40),'נתונים והנחות'!$F$40*0.1,0) | J27: =IF(ISNUMBER('נתונים והנחות'!$F$40),'נתונים והנחות'!$F$40*0.1,0) | K27: =IF(ISNUMBER('נתונים והנחות'!$F$40),'נתונים והנחות'!$F$40*0.1,0) | L27: =IF(ISNUMBER('נתונים והנחות'!$F$40),'נתונים והנחות'!$F$40*0.1,0) | M27: =IF(ISNUMBER('נתונים והנחות'!$F$40),'נתונים והנחות'!$F$40*0.1,0) | N27: =IF(ISNUMBER('נתונים והנחות'!$F$40),'נתונים והנחות'!$F$40*0.1,0) | ... P27: =IF(ISNUMBER('נתונים והנחות'!$F$40),'נתונים והנחות'!$F$40*0.1,0) | Q27: =0 | R27: =0 | S27: =0 | T27: =0 | U27: =0 | V27: =0 | W27: =0 | X27: =0 | ... Z27: =0
B28: מגן מס סטנדרטי — משאבות חום — 40 kW | C28: ₪ | D28: חישוב | F28: 0 | G28: =G27*'נתונים והנחות'!$F$10 | H28: =H27*'נתונים והנחות'!$F$10 | I28: =I27*'נתונים והנחות'!$F$10 | J28: =J27*'נתונים והנחות'!$F$10 | K28: =K27*'נתונים והנחות'!$F$10 | L28: =L27*'נתונים והנחות'!$F$10 | M28: =M27*'נתונים והנחות'!$F$10 | N28: =N27*'נתונים והנחות'!$F$10 | ... Z28: =Z27*'נתונים והנחות'!$F$10
B29: פחת מואץ — משאבות חום — 40 kW | C29: ₪ | D29: חישוב | F29: 0 | G29: =IF(ISNUMBER('נתונים והנחות'!$F$40),IF(1<=ROUND(1/(0.1*'נתונים והנחות'!$F$20),0),'נתונים והנחות'!$F$40*0.1*'נתונים והנחות'!$F$20,0),0) | H29: =IF(ISNUMBER('נתונים והנחות'!$F$40),IF(2<=ROUND(1/(0.1*'נתונים והנחות'!$F$20),0),'נתונים והנחות'!$F$40*0.1*'נתונים והנחות'!$F$20,0),0) | I29: =IF(ISNUMBER('נתונים והנחות'!$F$40),IF(3<=ROUND(1/(0.1*'נתונים והנחות'!$F$20),0),'נתונים והנחות'!$F$40*0.1*'נתונים והנחות'!$F$20,0),0) | J29: =IF(ISNUMBER('נתונים והנחות'!$F$40),IF(4<=ROUND(1/(0.1*'נתונים והנחות'!$F$20),0),'נתונים והנחות'!$F$40*0.1*'נתונים והנחות'!$F$20,0),0) | K29: =IF(ISNUMBER('נתונים והנחות'!$F$40),IF(5<=ROUND(1/(0.1*'נתונים והנחות'!$F$20),0),'נתונים והנחות'!$F$40*0.1*'נתונים והנחות'!$F$20,0),0) | L29: =IF(ISNUMBER('נתונים והנחות'!$F$40),IF(6<=ROUND(1/(0.1*'נתונים והנחות'!$F$20),0),'נתונים והנחות'!$F$40*0.1*'נתונים והנחות'!$F$20,0),0) | M29: =IF(ISNUMBER('נתונים והנחות'!$F$40),IF(7<=ROUND(1/(0.1*'נתונים והנחות'!$F$20),0),'נתונים והנחות'!$F$40*0.1*'נתונים והנחות'!$F$20,0),0) | N29: =IF(ISNUMBER('נתונים והנחות'!$F$40),IF(8<=ROUND(1/(0.1*'נתונים והנחות'!$F$20),0),'נתונים והנחות'!$F$40*0.1*'נתונים והנחות'!$F$20,0),0) | O29: =IF(ISNUMBER('נתונים והנחות'!$F$40),IF(9<=ROUND(1/(0.1*'נתונים והנחות'!$F$20),0),'נתונים והנחות'!$F$40*0.1*'נתונים והנחות'!$F$20,0),0) | P29: =IF(ISNUMBER('נתונים והנחות'!$F$40),IF(10<=ROUND(1/(0.1*'נתונים והנחות'!$F$20),0),'נתונים והנחות'!$F$40*0.1*'נתונים והנחות'!$F$20,0),0) | Q29: =IF(ISNUMBER('נתונים והנחות'!$F$40),IF(11<=ROUND(1/(0.1*'נתונים והנחות'!$F$20),0),'נתונים והנחות'!$F$40*0.1*'נתונים והנחות'!$F$20,0),0) | R29: =IF(ISNUMBER('נתונים והנחות'!$F$40),IF(12<=ROUND(1/(0.1*'נתונים והנחות'!$F$20),0),'נתונים והנחות'!$F$40*0.1*'נתונים והנחות'!$F$20,0),0) | S29: =IF(ISNUMBER('נתונים והנחות'!$F$40),IF(13<=ROUND(1/(0.1*'נתונים והנחות'!$F$20),0),'נתונים והנחות'!$F$40*0.1*'נתונים והנחות'!$F$20,0),0) | T29: =IF(ISNUMBER('נתונים והנחות'!$F$40),IF(14<=ROUND(1/(0.1*'נתונים והנחות'!$F$20),0),'נתונים והנחות'!$F$40*0.1*'נתונים והנחות'!$F$20,0),0) | U29: =IF(ISNUMBER('נתונים והנחות'!$F$40),IF(15<=ROUND(1/(0.1*'נתונים והנחות'!$F$20),0),'נתונים והנחות'!$F$40*0.1*'נתונים והנחות'!$F$20,0),0) | V29: =IF(ISNUMBER('נתונים והנחות'!$F$40),IF(16<=ROUND(1/(0.1*'נתונים והנחות'!$F$20),0),'נתונים והנחות'!$F$40*0.1*'נתונים והנחות'!$F$20,0),0) | W29: =IF(ISNUMBER('נתונים והנחות'!$F$40),IF(17<=ROUND(1/(0.1*'נתונים והנחות'!$F$20),0),'נתונים והנחות'!$F$40*0.1*'נתונים והנחות'!$F$20,0),0) | X29: =IF(ISNUMBER('נתונים והנחות'!$F$40),IF(18<=ROUND(1/(0.1*'נתונים והנחות'!$F$20),0),'נתונים והנחות'!$F$40*0.1*'נתונים והנחות'!$F$20,0),0) | Y29: =IF(ISNUMBER('נתונים והנחות'!$F$40),IF(19<=ROUND(1/(0.1*'נתונים והנחות'!$F$20),0),'נתונים והנחות'!$F$40*0.1*'נתונים והנחות'!$F$20,0),0) | Z29: =IF(ISNUMBER('נתונים והנחות'!$F$40),IF(20<=ROUND(1/(0.1*'נתונים והנחות'!$F$20),0),'נתונים והנחות'!$F$40*0.1*'נתונים והנחות'!$F$20,0),0)
B30: מגן מס מואץ — משאבות חום — 40 kW | C30: ₪ | D30: חישוב | F30: 0 | G30: =G29*'נתונים והנחות'!$F$10 | H30: =H29*'נתונים והנחות'!$F$10 | I30: =I29*'נתונים והנחות'!$F$10 | J30: =J29*'נתונים והנחות'!$F$10 | K30: =K29*'נתונים והנחות'!$F$10 | L30: =L29*'נתונים והנחות'!$F$10 | M30: =M29*'נתונים והנחות'!$F$10 | N30: =N29*'נתונים והנחות'!$F$10 | ... Z30: =Z29*'נתונים והנחות'!$F$10
B32: ג. ניתוח תזרים מזומנים — שלושה תרחישים
B33: פרמטר | C33: יחידות | D33: מקור | E33: הערות | F33: שנה 0 (השקעה) | G33: שנה 1 | H33: שנה 2 | I33: שנה 3 | J33: שנה 4 | K33: שנה 5 | L33: שנה 6 | M33: שנה 7 | N33: שנה 8 | O33: שנה 9 | P33: שנה 10 | Q33: שנה 11 | R33: שנה 12 | S33: שנה 13 | T33: שנה 14 | U33: שנה 15 | V33: שנה 16 | W33: שנה 17 | X33: שנה 18 | Y33: שנה 19 | Z33: שנה 20
B34: תרחיש A — רכישת תנור מזוט/סולר — 40 kW (ציוד קיים)
B35: השקעה ראשונית | C35: ₪ | D35: חישוב | F35: =IF(ISNUMBER('נתונים והנחות'!$F$39),-'נתונים והנחות'!$F$39,"PENDING")
B36: OPEX אנרגיה/דלק | C36: ₪ | D36: חישוב | F36: 0 | G36: =IF(ISNUMBER('נתונים והנחות'!$F$47),-'נתונים והנחות'!$F$47,0) | H36: =IF(ISNUMBER('נתונים והנחות'!$F$47),-'נתונים והנחות'!$F$47,0) | I36: =IF(ISNUMBER('נתונים והנחות'!$F$47),-'נתונים והנחות'!$F$47,0) | J36: =IF(ISNUMBER('נתונים והנחות'!$F$47),-'נתונים והנחות'!$F$47,0) | K36: =IF(ISNUMBER('נתונים והנחות'!$F$47),-'נתונים והנחות'!$F$47,0) | L36: =IF(ISNUMBER('נתונים והנחות'!$F$47),-'נתונים והנחות'!$F$47,0) | M36: =IF(ISNUMBER('נתונים והנחות'!$F$47),-'נתונים והנחות'!$F$47,0) | N36: =IF(ISNUMBER('נתונים והנחות'!$F$47),-'נתונים והנחות'!$F$47,0) | ... U36: =IF(ISNUMBER('נתונים והנחות'!$F$47),-'נתונים והנחות'!$F$47,0) | V36: =0 | W36: =0 | X36: =0 | Y36: =0 | Z36: =0
B37: OPEX אחר | C37: ₪ | D37: חישוב | F37: 0 | G37: =IF(ISNUMBER('נתונים והנחות'!$F$45),-'נתונים והנחות'!$F$45,0) | H37: =IF(ISNUMBER('נתונים והנחות'!$F$45),-'נתונים והנחות'!$F$45,0) | I37: =IF(ISNUMBER('נתונים והנחות'!$F$45),-'נתונים והנחות'!$F$45,0) | J37: =IF(ISNUMBER('נתונים והנחות'!$F$45),-'נתונים והנחות'!$F$45,0) | K37: =IF(ISNUMBER('נתונים והנחות'!$F$45),-'נתונים והנחות'!$F$45,0) | L37: =IF(ISNUMBER('נתונים והנחות'!$F$45),-'נתונים והנחות'!$F$45,0) | M37: =IF(ISNUMBER('נתונים והנחות'!$F$45),-'נתונים והנחות'!$F$45,0) | N37: =IF(ISNUMBER('נתונים והנחות'!$F$45),-'נתונים והנחות'!$F$45,0) | ... U37: =IF(ISNUMBER('נתונים והנחות'!$F$45),-'נתונים והנחות'!$F$45,0) | V37: =0 | W37: =0 | X37: =0 | Y37: =0 | Z37: =0
B38: תזרים נקי — A | C38: ₪ | D38: חישוב | F38: =F35 | G38: =G36+G37+G26 | H38: =H36+H37+H26 | I38: =I36+I37+I26 | J38: =J36+J37+J26 | K38: =K36+K37+K26 | L38: =L36+L37+L26 | M38: =M36+M37+M26 | N38: =N36+N37+N26 | ... Z38: =Z36+Z37+Z26
B39: תזרים מהוון — A | C39: ₪ | D39: חישוב | F39: =F38 | G39: =G38/(1+'נתונים והנחות'!$F$11)^1 | H39: =H38/(1+'נתונים והנחות'!$F$11)^2 | I39: =I38/(1+'נתונים והנחות'!$F$11)^3 | J39: =J38/(1+'נתונים והנחות'!$F$11)^4 | K39: =K38/(1+'נתונים והנחות'!$F$11)^5 | L39: =L38/(1+'נתונים והנחות'!$F$11)^6 | M39: =M38/(1+'נתונים והנחות'!$F$11)^7 | N39: =N38/(1+'נתונים והנחות'!$F$11)^8 | O39: =O38/(1+'נתונים והנחות'!$F$11)^9 | P39: =P38/(1+'נתונים והנחות'!$F$11)^10 | Q39: =Q38/(1+'נתונים והנחות'!$F$11)^11 | R39: =R38/(1+'נתונים והנחות'!$F$11)^12 | S39: =S38/(1+'נתונים והנחות'!$F$11)^13 | T39: =T38/(1+'נתונים והנחות'!$F$11)^14 | U39: =U38/(1+'נתונים והנחות'!$F$11)^15 | V39: =V38/(1+'נתונים והנחות'!$F$11)^16 | W39: =W38/(1+'נתונים והנחות'!$F$11)^17 | X39: =X38/(1+'נתונים והנחות'!$F$11)^18 | Y39: =Y38/(1+'נתונים והנחות'!$F$11)^19 | Z39: =Z38/(1+'נתונים והנחות'!$F$11)^20
B41: תרחיש B — רכישת משאבות חום — 40 kW | פחת סטנדרטי (ללא תמריץ)
B42: השקעה ראשונית | C42: ₪ | D42: חישוב | F42: =IF(ISNUMBER('נתונים והנחות'!$F$40),-'נתונים והנחות'!$F$40,"PENDING")
B43: OPEX אנרגיה (עם שחיקה) | C43: ₪ | D43: חישוב | F43: 0 | G43: =IF(ISNUMBER('נתונים והנחות'!$F$48),-'נתונים והנחות'!$F$48*(1-0.005)^0,0) | H43: =IF(ISNUMBER('נתונים והנחות'!$F$48),-'נתונים והנחות'!$F$48*(1-0.005)^1,0) | I43: =IF(ISNUMBER('נתונים והנחות'!$F$48),-'נתונים והנחות'!$F$48*(1-0.005)^2,0) | J43: =IF(ISNUMBER('נתונים והנחות'!$F$48),-'נתונים והנחות'!$F$48*(1-0.005)^3,0) | K43: =IF(ISNUMBER('נתונים והנחות'!$F$48),-'נתונים והנחות'!$F$48*(1-0.005)^4,0) | L43: =IF(ISNUMBER('נתונים והנחות'!$F$48),-'נתונים והנחות'!$F$48*(1-0.005)^5,0) | M43: =IF(ISNUMBER('נתונים והנחות'!$F$48),-'נתונים והנחות'!$F$48*(1-0.005)^6,0) | N43: =IF(ISNUMBER('נתונים והנחות'!$F$48),-'נתונים והנחות'!$F$48*(1-0.005)^7,0) | O43: =IF(ISNUMBER('נתונים והנחות'!$F$48),-'נתונים והנחות'!$F$48*(1-0.005)^8,0) | P43: =IF(ISNUMBER('נתונים והנחות'!$F$48),-'נתונים והנחות'!$F$48*(1-0.005)^9,0) | Q43: =0 | R43: =0 | S43: =0 | T43: =0 | U43: =0 | V43: =0 | W43: =0 | X43: =0 | ... Z43: =0
B44: OPEX אחר | C44: ₪ | D44: חישוב | F44: 0 | G44: =IF(ISNUMBER('נתונים והנחות'!$F$46),-'נתונים והנחות'!$F$46,0) | H44: =IF(ISNUMBER('נתונים והנחות'!$F$46),-'נתונים והנחות'!$F$46,0) | I44: =IF(ISNUMBER('נתונים והנחות'!$F$46),-'נתונים והנחות'!$F$46,0) | J44: =IF(ISNUMBER('נתונים והנחות'!$F$46),-'נתונים והנחות'!$F$46,0) | K44: =IF(ISNUMBER('נתונים והנחות'!$F$46),-'נתונים והנחות'!$F$46,0) | L44: =IF(ISNUMBER('נתונים והנחות'!$F$46),-'נתונים והנחות'!$F$46,0) | M44: =IF(ISNUMBER('נתונים והנחות'!$F$46),-'נתונים והנחות'!$F$46,0) | N44: =IF(ISNUMBER('נתונים והנחות'!$F$46),-'נתונים והנחות'!$F$46,0) | ... P44: =IF(ISNUMBER('נתונים והנחות'!$F$46),-'נתונים והנחות'!$F$46,0) | Q44: =0 | R44: =0 | S44: =0 | T44: =0 | U44: =0 | V44: =0 | W44: =0 | X44: =0 | ... Z44: =0
B45: תזרים נקי — B | C45: ₪ | D45: חישוב | F45: =F42 | G45: =G43+G44+G28 | H45: =H43+H44+H28 | I45: =I43+I44+I28 | J45: =J43+J44+J28 | K45: =K43+K44+K28 | L45: =L43+L44+L28 | M45: =M43+M44+M28 | N45: =N43+N44+N28 | ... Z45: =Z43+Z44+Z28
B46: תזרים מהוון — B | C46: ₪ | D46: חישוב | F46: =F45 | G46: =G45/(1+'נתונים והנחות'!$F$11)^1 | H46: =H45/(1+'נתונים והנחות'!$F$11)^2 | I46: =I45/(1+'נתונים והנחות'!$F$11)^3 | J46: =J45/(1+'נתונים והנחות'!$F$11)^4 | K46: =K45/(1+'נתונים והנחות'!$F$11)^5 | L46: =L45/(1+'נתונים והנחות'!$F$11)^6 | M46: =M45/(1+'נתונים והנחות'!$F$11)^7 | N46: =N45/(1+'נתונים והנחות'!$F$11)^8 | O46: =O45/(1+'נתונים והנחות'!$F$11)^9 | P46: =P45/(1+'נתונים והנחות'!$F$11)^10 | Q46: =Q45/(1+'נתונים והנחות'!$F$11)^11 | R46: =R45/(1+'נתונים והנחות'!$F$11)^12 | S46: =S45/(1+'נתונים והנחות'!$F$11)^13 | T46: =T45/(1+'נתונים והנחות'!$F$11)^14 | U46: =U45/(1+'נתונים והנחות'!$F$11)^15 | V46: =V45/(1+'נתונים והנחות'!$F$11)^16 | W46: =W45/(1+'נתונים והנחות'!$F$11)^17 | X46: =X45/(1+'נתונים והנחות'!$F$11)^18 | Y46: =Y45/(1+'נתונים והנחות'!$F$11)^19 | Z46: =Z45/(1+'נתונים והנחות'!$F$11)^20
...
